#VRML_SIM R2022a utf8
WorldInfo {
  basicTimeStep 16
  FPS 30
  contactProperties [
    ContactProperties {
      material1 "cacao"
      material2 "separator"
      bounce 1
      bounceVelocity 0.1
    }
    ContactProperties {
      material1 "cacao"
      material2 "lolipop_head"
      coulombFriction [
        7
      ]
      bounce 0
      bounceVelocity 0
    }
    ContactProperties {
      material1 "cacao"
      material2 "floor"
      coulombFriction [
        2
      ]
      forceDependentSlip [
        0.001
      ]
    }
    ContactProperties {
      material1 "cacao"
      material2 "guide"
      bounce 0.05
      forceDependentSlip [
        0.001
      ]
    }
    ContactProperties {
      material1 "wheel"
      material2 "floor"
      forceDependentSlip [
        0.001
      ]
    }
  ]
}
Viewpoint {
  orientation 0.3017471444532816 -0.5849896746012514 -0.7528185315361282 5.207718880638878
  position -7.5513567766214855 -8.132663667523174 9.398854262789287
  follow "cacaobot"
  followType "None"
  bloomThreshold 10
}
TexturedBackground {
  skybox FALSE
}
TexturedBackgroundLight {
  castShadows FALSE
}
RectangleArena {
  rotation 0 1 0 0
  contactMaterial "floor"
  floorSize 12 12
  floorTileSize 1 1
  wallHeight 1.5
}
DEF cacaobot Robot {
  translation 0 -1.06 -0.0190075
  rotation 0.9999965831069 9.589756002083231e-09 -0.002614148910175633 5.30716e-06
  children [
    DEF Body Group {
      children [
        Transform {
          translation 0 -0.696 0.416
          rotation 0 1 0 0
          children [
            Shape {
              appearance PBRAppearance {
                baseColor 0 0.666667 0.498039
                roughness 1
                metalness 0
              }
              geometry DEF back Box {
                size 0.656 0.56 0.48
              }
            }
          ]
        }
        Transform {
          translation -0.312 -0.008 0.272
          children [
            Shape {
              appearance DEF frame PBRAppearance {
                baseColor 0 0.333333 1
                roughness 1
                metalness 0
              }
              geometry Box {
                size 0.04 0.96 0.08
              }
            }
          ]
        }
        Transform {
          translation 0.304 -0.008 0.2723
          children [
            Shape {
              appearance DEF frame PBRAppearance {
                baseColor 0 0.333333 1
                roughness 1
                metalness 0
              }
              geometry Box {
                size 0.04 0.96 0.08
              }
            }
          ]
        }
        Transform {
          translation 0.264 -0.181916 0.418418
          rotation 1 0 0 -0.523595307179586
          children [
            Shape {
              appearance USE frame
              geometry Box {
                size 0.05 0.8 0.04
              }
            }
          ]
        }
        Transform {
          translation -0.272 -0.181916 0.418418
          rotation 1 0 0 -0.523595307179586
          children [
            Shape {
              appearance USE frame
              geometry Box {
                size 0.04 0.8 0.08
              }
            }
          ]
        }
        Transform {
          translation 0.182 0.0312 0.34
          rotation 0 1 0 0
          children [
            Shape {
              appearance DEF separator_apperance PBRAppearance {
                baseColor 1 1 0.498039
                roughness 1
                metalness 0
              }
              geometry Box {
                size 0.08 0.016 0.016
              }
            }
          ]
        }
        Transform {
          translation -0.184 0.032 0.34
          rotation 0 1 0 0
          children [
            Shape {
              appearance DEF separator_apperance PBRAppearance {
                baseColor 1 1 0.498039
                roughness 1
                metalness 0
              }
              geometry Box {
                size 0.08 0.016 0.016
              }
            }
          ]
        }
        Transform {
          translation -0.382 -0.321916 0.278418
          rotation 1 0 0 3.46682e-06
          children [
            Shape {
              appearance USE frame
              geometry Box {
                size 0.08 0.15 0.08
              }
            }
          ]
        }
        Transform {
          translation 0.368 -0.321916 0.278418
          rotation 1 0 0 3.46682e-06
          children [
            Shape {
              appearance USE frame
              geometry Box {
                size 0.08 0.15 0.08
              }
            }
          ]
        }
      ]
    }
    HingeJoint {
      jointParameters HingeJointParameters {
        axis -1 0 0
        anchor -0.386 0 0.248054
      }
      device [
        RotationalMotor {
          name "wheel1"
        }
      ]
      endPoint Solid {
        translation -0.38654450023376774 -0.0008689798914523449 0.25098822719027647
        rotation 0.000719331700319439 -0.99999959792545 -0.0005354538666399636 1.570647656717876
        children [
          Shape {
            appearance DEF wheel_appearance PBRAppearance {
              baseColor 0 0 0
              roughness 1
              metalness 0
            }
            geometry DEF wheel_shape Cylinder {
              height 0.08
              radius 0.24
            }
          }
        ]
        name "wheel1"
        contactMaterial "wheel"
        boundingObject USE wheel_shape
        physics DEF wheel_ph Physics {
          density -1
          mass 2
        }
      }
    }
    HingeJoint {
      jointParameters HingeJointParameters {
        axis -1 0 0
        anchor 0.376 0 0.248
      }
      device [
        RotationalMotor {
          name "wheel2"
        }
      ]
      endPoint Solid {
        translation 0.3755027209922345 -0.0008774491631861095 0.2509516415728788
        rotation -0.0005245759061837711 -0.9999996934552393 0.000581299876256074 1.570546219759433
        children [
          Shape {
            appearance USE wheel_appearance
            geometry USE wheel_shape
          }
        ]
        name "wheel2"
        contactMaterial "wheel"
        boundingObject USE wheel_shape
        physics USE wheel_ph
      }
    }
    HingeJoint {
      jointParameters HingeJointParameters {
        axis -1 0 0
        anchor -0.376 -0.648 0.248
      }
      device [
        RotationalMotor {
          name "wheel3"
        }
      ]
      endPoint Solid {
        translation -0.3754742574749055 -0.6481417209767698 0.2485796829665002
        rotation 0.003579465772562545 -0.9999869193210953 -0.003653575165257277 1.5708297312425616
        children [
          Shape {
            appearance USE wheel_appearance
            geometry USE wheel_shape
          }
        ]
        name "wheel3"
        contactMaterial "wheel"
        boundingObject USE wheel_shape
        physics USE wheel_ph
      }
    }
    HingeJoint {
      jointParameters HingeJointParameters {
        axis -1 0 0
        anchor 0.376 -0.648 0.247998
      }
      device [
        RotationalMotor {
          name "wheel4"
        }
      ]
      endPoint Solid {
        translation 0.37653955852096066 -0.6485198846347306 0.24859952211564484
        rotation -0.002587236323851137 -0.9999931554378992 0.0026448602152506656 1.570883322942942
        children [
          Shape {
            appearance USE wheel_appearance
            geometry USE wheel_shape
          }
        ]
        name "wheel4"
        contactMaterial "wheel"
        boundingObject USE wheel_shape
        physics DEF wheel_ph Physics {
          density -1
          mass 1
        }
      }
    }
    Transform {
      translation 0.224 0 0.284
      rotation 0 1 0 0
      children [
        Shape {
          appearance USE frame
          geometry Box {
            size 0.136 0.096 0.096
          }
        }
      ]
    }
    Transform {
      translation -0.224 0 0.284
      rotation 0 1 0 0
      children [
        Shape {
          appearance USE frame
          geometry Box {
            size 0.136 0.096 0.096
          }
        }
      ]
    }
    HingeJoint {
      jointParameters HingeJointParameters {
        axis -1 0 0
        anchor -0.8 0 0.29
      }
      device [
        RotationalMotor {
          name "disks"
        }
      ]
      endPoint Solid {
        translation 2.4992712523985716e-06 0.00326035773283754 0.2883118426260892
        rotation 0.6566738258669461 -0.3716252341832796 -0.6562577022325073 2.428209759024916
        children [
          Shape {
            appearance PBRAppearance {
              roughness 1
              metalness 0
            }
            geometry DEF disk_holder Cylinder {
              height 0.36
              radius 0.036
              subdivision 8
            }
            castShadows FALSE
          }
          Solid {
            translation 0 0 -0.138
            rotation 0 1 0 0
            children [
              DEF disk Group {
                children [
                  Shape {
                    appearance PBRAppearance {
                      baseColor 0.223529 0.223529 0.223529
                      metalness 0
                    }
                    geometry Cylinder {
                      height 0.03048
                      radius 0.1216
                    }
                    castShadows FALSE
                  }
                ]
              }
              BallJoint {
                jointParameters BallJointParameters {
                  anchor 0 0.12 0
                  springConstant 2
                  dampingConstant 1e-06
                }
                endPoint Solid {
                  translation -0.0028677823937523447 0.17664130031516756 -0.0048144438251334415
                  rotation -0.9994770024096101 -0.021831932945447677 0.023855572895358897 1.6566811510088362
                  children [
                    DEF lolipop_group Group {
                      children [
                        Shape {
                          appearance PBRAppearance {
                            baseColor 0.360784 0.360784 0
                            metalness 0
                          }
                          geometry Cylinder {
                            height 0.116
                            radius 0.00325
                            subdivision 3
                          }
                        }
                      ]
                    }
                    Solid {
                      translation 0 0 0.06
                      children [
                        DEF ball Shape {
                          appearance DEF lolipop_base_color PBRAppearance {
                            baseColor 1 1 0
                            roughness 1
                            metalness 0
                          }
                          geometry DEF ball Sphere {
                            radius 0.02
                            subdivision 2
                          }
                        }
                      ]
                      contactMaterial "lolipop_head"
                      boundingObject USE ball
                      physics Physics {
                      }
                    }
                  ]
                  name "lollipop"
                  contactMaterial "cacao_pickup"
                  boundingObject USE lolipop_group
                  physics DEF lollipop_ph Physics {
                    density -1
                    mass 0.1
                    centerOfMass [
                      0 0 0
                    ]
                    inertiaMatrix [
                      5.7e-05 5.7e-05 9.7e-06
                      0 0 0
                    ]
                  }
                }
              }
              BallJoint {
                jointParameters BallJointParameters {
                  anchor 0 -0.12 0
                  springConstant 2
                  dampingConstant 1e-06
                }
                endPoint Solid {
                  translation -0.0031651810300218413 -0.17673245857586664 -0.006183206966961248
                  rotation -0.020204600384126137 -0.7440672907754438 0.6677991022166838 3.096049503243397
                  children [
                    USE lolipop_group
                    Solid {
                      translation 0 0 0.06
                      children [
                        Shape {
                          appearance USE lolipop_base_color
                          geometry USE ball
                        }
                      ]
                      contactMaterial "lolipop_head"
                      boundingObject USE ball
                      physics Physics {
                      }
                    }
                  ]
                  name "lollipop(1)"
                  contactMaterial "cacao_pickup"
                  boundingObject USE lolipop_group
                  physics USE lollipop_ph
                }
              }
              BallJoint {
                jointParameters BallJointParameters {
                  anchor -0.12 0 0
                  springConstant 2
                  dampingConstant 1e-06
                }
                endPoint Solid {
                  translation -0.17652899972946243 0.0069588542727947065 -7.287502172514834e-05
                  rotation -0.6286461772624252 -0.546940791820825 0.5528650414484064 2.028737267154834
                  children [
                    Solid {
                      translation 0 0 0.06
                      children [
                        Shape {
                          appearance USE lolipop_base_color
                          geometry USE ball
                        }
                      ]
                      contactMaterial "lolipop_head"
                      boundingObject USE ball
                      physics Physics {
                      }
                    }
                    USE lolipop_group
                  ]
                  name "lollipop(2)"
                  contactMaterial "cacao_pickup"
                  boundingObject USE lolipop_group
                  physics USE lollipop_ph
                }
              }
              BallJoint {
                jointParameters BallJointParameters {
                  anchor 0.12 0 0
                  springConstant 2
                  dampingConstant 1e-06
                }
                endPoint Solid {
                  translation 0.17642815351691588 0.008332586533517554 0.0002680776871603546
                  rotation -0.6271308091346147 0.5591420224416405 -0.5422795837702502 1.9933070162316067
                  children [
                    USE lolipop_group
                    Solid {
                      translation 0 0 0.06
                      children [
                        Shape {
                          appearance USE lolipop_base_color
                          geometry USE ball
                        }
                      ]
                      contactMaterial "lolipop_head"
                      boundingObject USE ball
                      physics Physics {
                      }
                    }
                  ]
                  name "lollipop(3)"
                  contactMaterial "cacao_pickup"
                  boundingObject USE lolipop_group
                  physics USE lollipop_ph
                }
              }
              BallJoint {
                jointParameters BallJointParameters {
                  anchor 0.11551 -0.0375066 0
                  springConstant 2
                  dampingConstant 1e-06
                }
                endPoint Solid {
                  translation 0.17210761935476443 -0.04492141646579174 -0.00043700303282600357
                  rotation -0.5160812179187824 0.6220747769843455 -0.5887980539636176 2.1439681001994995
                  children [
                    Solid {
                      translation 0 0 0.06
                      children [
                        Shape {
                          appearance USE lolipop_base_color
                          geometry USE ball
                        }
                      ]
                      contactMaterial "lolipop_head"
                      boundingObject USE ball
                      physics Physics {
                      }
                    }
                    USE lolipop_group
                  ]
                  name "lollipop(4)"
                  contactMaterial "cacao_pickup"
                  boundingObject USE lolipop_group
                  physics USE lollipop_ph
                }
              }
              BallJoint {
                jointParameters BallJointParameters {
                  anchor 0.098704 -0.0696 0
                  springConstant 2
                  dampingConstant 1e-06
                }
                endPoint Solid {
                  translation 0.15090172126796914 -0.09271494581822226 -0.0018218720814109999
                  rotation -0.4039387498757278 0.6710581211000969 -0.6217028908203998 2.3209147196094975
                  children [
                    Solid {
                      translation 0 0 0.06
                      children [
                        Shape {
                          appearance USE lolipop_base_color
                          geometry USE ball
                        }
                      ]
                      contactMaterial "lolipop_head"
                      boundingObject USE ball
                      physics Physics {
                      }
                    }
                    USE lolipop_group
                  ]
                  name "lollipop(6)"
                  contactMaterial "cacao_pickup"
                  boundingObject USE lolipop_group
                  physics USE lollipop_ph
                }
              }
              BallJoint {
                jointParameters BallJointParameters {
                  anchor -0.11551 0.0375066 0
                  springConstant 2
                  dampingConstant 1e-06
                }
                endPoint Solid {
                  translation -0.16870379779483113 0.05783972937882545 -0.0006898882154748373
                  rotation -0.7243146708888586 -0.4788105174644995 0.4960934850414213 1.9208131646470699
                  children [
                    USE lolipop_group
                    Solid {
                      translation 0 0 0.06
                      children [
                        Shape {
                          appearance USE lolipop_base_color
                          geometry USE ball
                        }
                      ]
                      contactMaterial "lolipop_head"
                      boundingObject USE ball
                      physics Physics {
                      }
                    }
                  ]
                  name "lollipop(5)"
                  contactMaterial "cacao_pickup"
                  boundingObject USE lolipop_group
                  physics USE lollipop_ph
                }
              }
              BallJoint {
                jointParameters BallJointParameters {
                  anchor -0.098704 0.0696 0
                  springConstant 2
                  dampingConstant 1e-06
                }
                endPoint Solid {
                  translation -0.14562014372444737 0.101815432103535 -0.0017805641120483776
                  rotation -0.8113529024430395 -0.4013788117018366 0.4249723722950441 1.8329325145627209
                  children [
                    USE lolipop_group
                    Solid {
                      translation 0 0 0.06
                      children [
                        Shape {
                          appearance USE lolipop_base_color
                          geometry USE ball
                        }
                      ]
                      contactMaterial "lolipop_head"
                      boundingObject USE ball
                      physics Physics {
                      }
                    }
                  ]
                  name "lollipop(7)"
                  contactMaterial "cacao_pickup"
                  boundingObject USE lolipop_group
                  physics USE lollipop_ph
                }
              }
              BallJoint {
                jointParameters BallJointParameters {
                  anchor 0.0733888 -0.097236 0
                  springConstant 2
                  dampingConstant 1e-06
                }
                endPoint Solid {
                  translation 0.11167052735297754 -0.13935849526213961 -0.005248062453927742
                  rotation 0.48333169139472776 0.833210126517438 -0.26861005409758326 1.7485448999701159
                  children [
                    USE lolipop_group
                    Solid {
                      translation 0 0 0.06
                      children [
                        Shape {
                          appearance USE lolipop_base_color
                          geometry USE ball
                        }
                      ]
                      contactMaterial "lolipop_head"
                      boundingObject USE ball
                      physics Physics {
                      }
                    }
                  ]
                  name "lollipop(8)"
                  contactMaterial "cacao_pickup"
                  boundingObject USE lolipop_group
                  physics USE lollipop_ph
                }
              }
              BallJoint {
                jointParameters BallJointParameters {
                  anchor -0.0733888 0.097236 0
                  springConstant 2
                  dampingConstant 1e-06
                }
                endPoint Solid {
                  translation -0.1074410794153719 0.1427103463978246 -0.0034835225552554954
                  rotation -0.7041623418902683 0.3104788924371987 0.638559514543933 2.444674839762517
                  children [
                    USE lolipop_group
                    Solid {
                      translation 0 0 0.06
                      children [
                        Shape {
                          appearance USE lolipop_base_color
                          geometry USE ball
                        }
                      ]
                      contactMaterial "lolipop_head"
                      boundingObject USE ball
                      physics Physics {
                      }
                    }
                  ]
                  name "lollipop(9)"
                  contactMaterial "cacao_pickup"
                  boundingObject USE lolipop_group
                  physics USE lollipop_ph
                }
              }
              BallJoint {
                jointParameters BallJointParameters {
                  anchor -0.038562 0.11354 0
                  springConstant 2
                  dampingConstant 1e-06
                }
                endPoint Solid {
                  translation -0.06297931186712578 0.1691434680188267 -0.004984298148375152
                  rotation -0.9604169523079977 -0.12363543264127153 0.2496268365280926 1.7240808295527366
                  children [
                    USE lolipop_group
                    Solid {
                      translation 0 0 0.06
                      children [
                        Shape {
                          appearance USE lolipop_base_color
                          geometry USE ball
                        }
                      ]
                      contactMaterial "lolipop_head"
                      boundingObject USE ball
                      physics Physics {
                      }
                    }
                  ]
                  name "lollipop(10)"
                  contactMaterial "cacao_pickup"
                  boundingObject USE lolipop_group
                  physics USE lollipop_ph
                }
              }
              BallJoint {
                jointParameters BallJointParameters {
                  anchor 0.038562 -0.11354 0.000301598
                  springConstant 2
                  dampingConstant 1e-06
                }
                endPoint Solid {
                  translation 0.06401467876653621 -0.16881863459304589 -0.00629664334796569
                  rotation -0.1855717271531422 0.7260519640503031 -0.6621266340966031 2.904532273505881
                  children [
                    USE lolipop_group
                    Solid {
                      translation 0 0 0.06
                      children [
                        Shape {
                          appearance USE lolipop_base_color
                          geometry USE ball
                        }
                      ]
                      contactMaterial "lolipop_head"
                      boundingObject USE ball
                      physics Physics {
                      }
                    }
                  ]
                  name "lollipop(11)"
                  contactMaterial "cacao_pickup"
                  boundingObject USE lolipop_group
                  physics USE lollipop_ph
                }
              }
              BallJoint {
                jointParameters BallJointParameters {
                  anchor -0.113802 -0.042415 0
                  springConstant 2
                  dampingConstant 1e-06
                }
                endPoint Solid {
                  translation -0.17313412881939746 -0.056693120655967356 -0.00015506487881788126
                  rotation 0.13068670165022253 -0.9865180320025706 0.09850461179843763 1.5782743625379339
                  children [
                    USE lolipop_group
                    Solid {
                      translation 0 0 0.06
                      children [
                        Shape {
                          appearance USE lolipop_base_color
                          geometry USE ball
                        }
                      ]
                      contactMaterial "lolipop_head"
                      boundingObject USE ball
                      physics Physics {
                      }
                    }
                  ]
                  name "lollipop(12)"
                  contactMaterial "cacao_pickup"
                  boundingObject USE lolipop_group
                  physics USE lollipop_ph
                }
              }
              BallJoint {
                jointParameters BallJointParameters {
                  anchor -0.0947202 -0.07136 0
                  springConstant 2
                  dampingConstant 1e-06
                }
                endPoint Solid {
                  translation -0.14716706592960022 -0.10259587032052264 -0.0012197785852815538
                  rotation 0.28474364180522244 -0.9318028457354914 0.22508779427312176 1.6344856358820714
                  children [
                    USE lolipop_group
                    Solid {
                      translation 0 0 0.06
                      children [
                        Shape {
                          appearance USE lolipop_base_color
                          geometry USE ball
                        }
                      ]
                      contactMaterial "lolipop_head"
                      boundingObject USE ball
                      physics Physics {
                      }
                    }
                  ]
                  name "lollipop(14)"
                  contactMaterial "cacao_pickup"
                  boundingObject USE lolipop_group
                  physics USE lollipop_ph
                }
              }
              BallJoint {
                jointParameters BallJointParameters {
                  anchor 0.113802 0.042415 0.00149135
                  springConstant 2
                  dampingConstant 1e-06
                }
                endPoint Solid {
                  translation 0.16605714994457263 0.07391602501002317 0.0007954550473493146
                  rotation -0.6980237770265066 -0.19313599904223339 -0.6895370132049535 2.762264279048422
                  children [
                    USE lolipop_group
                    Solid {
                      translation 0 0 0.06
                      children [
                        Shape {
                          appearance USE lolipop_base_color
                          geometry USE ball
                        }
                      ]
                      contactMaterial "lolipop_head"
                      boundingObject USE ball
                      physics Physics {
                      }
                    }
                  ]
                  name "lollipop(13)"
                  contactMaterial "cacao_pickup"
                  boundingObject USE lolipop_group
                  physics USE lollipop_ph
                }
              }
              BallJoint {
                jointParameters BallJointParameters {
                  anchor 0.0947202 0.0713605 0.00320256
                  springConstant 2
                  dampingConstant 1e-06
                }
                endPoint Solid {
                  translation 0.13579639975252383 0.1163458418029677 0.0005252031922724594
                  rotation -0.6866549149228398 -0.30619185701450624 -0.6593569401396453 2.582871017781336
                  children [
                    USE lolipop_group
                    Solid {
                      translation 0 0 0.06
                      children [
                        Shape {
                          appearance USE lolipop_base_color
                          geometry USE ball
                        }
                      ]
                      contactMaterial "lolipop_head"
                      boundingObject USE ball
                      physics Physics {
                      }
                    }
                  ]
                  name "lollipop(15)"
                  contactMaterial "cacao_pickup"
                  boundingObject USE lolipop_group
                  physics USE lollipop_ph
                }
              }
              BallJoint {
                jointParameters BallJointParameters {
                  anchor -0.070822 -0.0947397 7.5131e-08
                  springConstant 2
                  dampingConstant 1e-06
                }
                endPoint Solid {
                  translation -0.10805590832493225 -0.1430459696684706 -0.004189437916632387
                  rotation 0.43112356918263495 -0.8265076535546536 0.36196348809072765 1.8016073398901102
                  children [
                    USE lolipop_group
                    Solid {
                      translation 0 0 0.06
                      children [
                        Shape {
                          appearance USE lolipop_base_color
                          geometry USE ball
                        }
                      ]
                      contactMaterial "lolipop_head"
                      boundingObject USE ball
                      physics Physics {
                      }
                    }
                  ]
                  name "lollipop(16)"
                  contactMaterial "cacao_pickup"
                  boundingObject USE lolipop_group
                  physics USE lollipop_ph
                }
              }
              BallJoint {
                jointParameters BallJointParameters {
                  anchor -0.037118 -0.11271 0
                  springConstant 2
                  dampingConstant 1e-06
                }
                endPoint Solid {
                  translation -0.058815240575719706 -0.16958917215733532 -0.005943263177315304
                  rotation 0.5193008846749666 -0.7286620264803411 0.4465179081978236 1.9491921784246484
                  children [
                    USE lolipop_group
                    Solid {
                      translation 0 0 0.06
                      children [
                        Shape {
                          appearance USE lolipop_base_color
                          geometry USE ball
                        }
                      ]
                      contactMaterial "lolipop_head"
                      boundingObject USE ball
                      physics Physics {
                      }
                    }
                  ]
                  name "lollipop(18)"
                  contactMaterial "cacao_pickup"
                  boundingObject USE lolipop_group
                  physics USE lollipop_ph
                }
              }
              BallJoint {
                jointParameters BallJointParameters {
                  anchor 0.070822 0.0947397 0
                  springConstant 2
                  dampingConstant 1e-06
                }
                endPoint Solid {
                  translation 0.09529997756138614 0.15042897152820095 -0.0037594277764975152
                  rotation -0.649889993591721 -0.4369832804749166 -0.6218429132946144 2.391732224216717
                  children [
                    USE lolipop_group
                    Solid {
                      translation 0 0 0.06
                      children [
                        Shape {
                          appearance USE lolipop_base_color
                          geometry USE ball
                        }
                      ]
                      contactMaterial "lolipop_head"
                      boundingObject USE ball
                      physics Physics {
                      }
                    }
                  ]
                  name "lollipop(17)"
                  contactMaterial "cacao_pickup"
                  boundingObject USE lolipop_group
                  physics USE lollipop_ph
                }
              }
              BallJoint {
                jointParameters BallJointParameters {
                  anchor 0.037118 0.11271 0
                  springConstant 2
                  dampingConstant 1e-06
                }
                endPoint Solid {
                  translation 0.04791808360976291 0.1724796179810434 -0.004902004168861399
                  rotation -0.6215022414637189 -0.5263637193849912 -0.5802380535355912 2.251817613719185
                  children [
                    USE lolipop_group
                    Solid {
                      translation 0 0 0.06
                      children [
                        Shape {
                          appearance USE lolipop_base_color
                          geometry USE ball
                        }
                      ]
                      contactMaterial "lolipop_head"
                      boundingObject USE ball
                      physics Physics {
                      }
                    }
                  ]
                  name "lollipop(19)"
                  contactMaterial "cacao_pickup"
                  boundingObject USE lolipop_group
                  physics USE lollipop_ph
                }
              }
            ]
            name "solid(10)"
            contactMaterial ""
            boundingObject USE disk
            physics Physics {
              density -1
              mass 1
              centerOfMass [
                0.0004964075240797066 0 2.6683962694384078e-09
              ]
              inertiaMatrix [
                0.015474887112992634 0.015695834201723817 0.030518910912255608
                0 -1.1783490361212277e-09 0
              ]
              damping Damping {
                linear 0.715292
                angular 0.715292
              }
            }
          }
          Solid {
            translation 0 0 0.042
            rotation 0 0 1 -0.261795307179586
            children [
              DEF disk Group {
                children [
                  Shape {
                    appearance PBRAppearance {
                      baseColor 0.223529 0.223529 0.223529
                      metalness 0
                    }
                    geometry Cylinder {
                      height 0.03048
                      radius 0.1216
                    }
                    castShadows FALSE
                  }
                ]
              }
              BallJoint {
                jointParameters BallJointParameters {
                  anchor 0 0.12 0
                  springConstant 2
                  dampingConstant 1e-06
                }
                endPoint Solid {
                  translation -7.820120636528093e-17 0.17600000000000043 -1.6805133673525319e-16
                  rotation -0.9999999999999999 -3.9850518124929626e-16 -4.774540376820832e-16 1.5707953071790188
                  children [
                    DEF lolipop_group Group {
                      children [
                        Shape {
                          appearance PBRAppearance {
                            baseColor 0.360784 0.360784 0
                            metalness 0
                          }
                          geometry Cylinder {
                            height 0.116
                            radius 0.00325
                            subdivision 3
                          }
                        }
                      ]
                    }
                    Solid {
                      translation 0 0 0.06
                      children [
                        DEF ball Shape {
                          appearance DEF lolipop_base_color PBRAppearance {
                            baseColor 1 1 0
                            roughness 1
                            metalness 0
                          }
                          geometry DEF ball Sphere {
                            radius 0.02
                            subdivision 2
                          }
                        }
                      ]
                      contactMaterial "lolipop_head"
                      boundingObject USE ball
                      physics Physics {
                      }
                    }
                  ]
                  name "lollipop"
                  contactMaterial "cacao_pickup"
                  boundingObject USE lolipop_group
                  physics DEF lollipop_ph Physics {
                    density -1
                    mass 0.1
                    centerOfMass [
                      0 0 0
                    ]
                    inertiaMatrix [
                      5.7e-05 5.7e-05 9.7e-06
                      0 0 0
                    ]
                  }
                }
              }
              BallJoint {
                jointParameters BallJointParameters {
                  anchor 0 -0.12 0
                  springConstant 2
                  dampingConstant 1e-06
                }
                endPoint Solid {
                  translation 1.3168199992380346e-07 -0.17599999999999844 -9.899470003639369e-08
                  rotation -3.3905001907426213e-09 0.7071072811865724 -0.7071062811861692 3.1415900000000008
                  children [
                    USE lolipop_group
                    Solid {
                      translation 0 0 0.06
                      children [
                        Shape {
                          appearance USE lolipop_base_color
                          geometry USE ball
                        }
                      ]
                      contactMaterial "lolipop_head"
                      boundingObject USE ball
                      physics Physics {
                      }
                    }
                  ]
                  name "lollipop(1)"
                  contactMaterial "cacao_pickup"
                  boundingObject USE lolipop_group
                  physics USE lollipop_ph
                }
              }
              BallJoint {
                jointParameters BallJointParameters {
                  anchor -0.12 0 0
                  springConstant 2
                  dampingConstant 1e-06
                }
                endPoint Solid {
                  translation -0.17599999999999583 -8.910470000103726e-08 -8.91046999424867e-08
                  rotation -0.577349602522641 -0.5773516025212898 0.5773496025226371 2.0943953071793167
                  children [
                    Solid {
                      translation 0 0 0.06
                      children [
                        Shape {
                          appearance USE lolipop_base_color
                          geometry USE ball
                        }
                      ]
                      contactMaterial "lolipop_head"
                      boundingObject USE ball
                      physics Physics {
                      }
                    }
                    USE lolipop_group
                  ]
                  name "lollipop(2)"
                  contactMaterial "cacao_pickup"
                  boundingObject USE lolipop_group
                  physics USE lollipop_ph
                }
              }
              BallJoint {
                jointParameters BallJointParameters {
                  anchor 0.12 0 0
                  springConstant 2
                  dampingConstant 1e-06
                }
                endPoint Solid {
                  translation 0.17599999999999988 5.67750931334062e-17 -1.4709616513665542e-16
                  rotation -0.5773499358561497 0.577350935856013 -0.5773499358561373 2.094389999999932
                  children [
                    USE lolipop_group
                    Solid {
                      translation 0 0 0.06
                      children [
                        Shape {
                          appearance USE lolipop_base_color
                          geometry USE ball
                        }
                      ]
                      contactMaterial "lolipop_head"
                      boundingObject USE ball
                      physics Physics {
                      }
                    }
                  ]
                  name "lollipop(3)"
                  contactMaterial "cacao_pickup"
                  boundingObject USE lolipop_group
                  physics USE lollipop_ph
                }
              }
              BallJoint {
                jointParameters BallJointParameters {
                  anchor 0.11551 -0.0375066 0
                  springConstant 2
                  dampingConstant 1e-06
                }
                endPoint Solid {
                  translation 0.16959999999999892 -0.05199999999999972 1.8285900001958585e-07
                  rotation -0.47690495958780593 0.6215159473336664 -0.6215139473338378 2.2515799999998696
                  children [
                    Solid {
                      translation 0 0 0.06
                      children [
                        Shape {
                          appearance USE lolipop_base_color
                          geometry USE ball
                        }
                      ]
                      contactMaterial "lolipop_head"
                      boundingObject USE ball
                      physics Physics {
                      }
                    }
                    USE lolipop_group
                  ]
                  name "lollipop(4)"
                  contactMaterial "cacao_pickup"
                  boundingObject USE lolipop_group
                  physics USE lollipop_ph
                }
              }
              BallJoint {
                jointParameters BallJointParameters {
                  anchor 0.098704 -0.0696 0
                  springConstant 2
                  dampingConstant 1e-06
                }
                endPoint Solid {
                  translation 0.1472000000000003 -0.09759999999999913 -3.3270299834629955e-09
                  rotation -0.3779641520502855 0.6546552633596848 -0.6546522633584723 2.4188499999999666
                  children [
                    Solid {
                      translation 0 0 0.06
                      children [
                        Shape {
                          appearance USE lolipop_base_color
                          geometry USE ball
                        }
                      ]
                      contactMaterial "lolipop_head"
                      boundingObject USE ball
                      physics Physics {
                      }
                    }
                    USE lolipop_group
                  ]
                  name "lollipop(6)"
                  contactMaterial "cacao_pickup"
                  boundingObject USE lolipop_group
                  physics USE lollipop_ph
                }
              }
              BallJoint {
                jointParameters BallJointParameters {
                  anchor -0.11551 0.0375066 0
                  springConstant 2
                  dampingConstant 1e-06
                }
                endPoint Solid {
                  translation -0.16959999999999567 0.05199999999999898 -3.38069999843801e-07
                  rotation -0.6776590404813123 -0.519993031062828 0.5199860310624119 1.9504453071794081
                  children [
                    USE lolipop_group
                    Solid {
                      translation 0 0 0.06
                      children [
                        Shape {
                          appearance USE lolipop_base_color
                          geometry USE ball
                        }
                      ]
                      contactMaterial "lolipop_head"
                      boundingObject USE ball
                      physics Physics {
                      }
                    }
                  ]
                  name "lollipop(5)"
                  contactMaterial "cacao_pickup"
                  boundingObject USE lolipop_group
                  physics USE lollipop_ph
                }
              }
              BallJoint {
                jointParameters BallJointParameters {
                  anchor -0.098704 0.0696 0
                  springConstant 2
                  dampingConstant 1e-06
                }
                endPoint Solid {
                  translation -0.14719999999999853 0.0975999999999982 1.9606499805077454e-08
                  rotation -0.7745939356444271 -0.44721896284370033 0.4472129628441938 1.8234753071793455
                  children [
                    USE lolipop_group
                    Solid {
                      translation 0 0 0.06
                      children [
                        Shape {
                          appearance USE lolipop_base_color
                          geometry USE ball
                        }
                      ]
                      contactMaterial "lolipop_head"
                      boundingObject USE ball
                      physics Physics {
                      }
                    }
                  ]
                  name "lollipop(7)"
                  contactMaterial "cacao_pickup"
                  boundingObject USE lolipop_group
                  physics USE lollipop_ph
                }
              }
              BallJoint {
                jointParameters BallJointParameters {
                  anchor 0.0733888 -0.097236 0
                  springConstant 2
                  dampingConstant 1e-06
                }
                endPoint Solid {
                  translation 0.10841799999999874 -0.1409159999999986 -0.0008662479999999588
                  rotation 0.4688593251243142 0.8160377347211736 -0.3380138292364795 1.7177799999997936
                  children [
                    USE lolipop_group
                    Solid {
                      translation 0 0 0.06
                      children [
                        Shape {
                          appearance USE lolipop_base_color
                          geometry USE ball
                        }
                      ]
                      contactMaterial "lolipop_head"
                      boundingObject USE ball
                      physics Physics {
                      }
                    }
                  ]
                  name "lollipop(8)"
                  contactMaterial "cacao_pickup"
                  boundingObject USE lolipop_group
                  physics USE lollipop_ph
                }
              }
              BallJoint {
                jointParameters BallJointParameters {
                  anchor -0.0733888 0.097236 0
                  springConstant 2
                  dampingConstant 1e-06
                }
                endPoint Solid {
                  translation -0.10841799999999881 0.1409159999999993 2.0220370516854658e-16
                  rotation -0.6987879380300878 0.27374397572384385 0.6608779413920257 2.415805307179535
                  children [
                    USE lolipop_group
                    Solid {
                      translation 0 0 0.06
                      children [
                        Shape {
                          appearance USE lolipop_base_color
                          geometry USE ball
                        }
                      ]
                      contactMaterial "lolipop_head"
                      boundingObject USE ball
                      physics Physics {
                      }
                    }
                  ]
                  name "lollipop(9)"
                  contactMaterial "cacao_pickup"
                  boundingObject USE lolipop_group
                  physics USE lollipop_ph
                }
              }
              BallJoint {
                jointParameters BallJointParameters {
                  anchor -0.038562 0.11354 0
                  springConstant 2
                  dampingConstant 1e-06
                }
                endPoint Solid {
                  translation -0.06282480000000001 0.16841599999999923 9.046279999980742e-05
                  rotation -0.9559370020737317 -0.14344101411476712 0.25614277958984827 1.6378353071793814
                  children [
                    USE lolipop_group
                    Solid {
                      translation 0 0 0.06
                      children [
                        Shape {
                          appearance USE lolipop_base_color
                          geometry USE ball
                        }
                      ]
                      contactMaterial "lolipop_head"
                      boundingObject USE ball
                      physics Physics {
                      }
                    }
                  ]
                  name "lollipop(10)"
                  contactMaterial "cacao_pickup"
                  boundingObject USE lolipop_group
                  physics USE lollipop_ph
                }
              }
              BallJoint {
                jointParameters BallJointParameters {
                  anchor 0.038562 -0.11354 0.000301598
                  springConstant 2
                  dampingConstant 1e-06
                }
                endPoint Solid {
                  translation 0.06282479999999949 -0.1684159999999978 0.00012063799999999665
                  rotation -0.18812399565348317 0.6867919841320226 -0.7020869837786254 2.9316699999999996
                  children [
                    USE lolipop_group
                    Solid {
                      translation 0 0 0.06
                      children [
                        Shape {
                          appearance USE lolipop_base_color
                          geometry USE ball
                        }
                      ]
                      contactMaterial "lolipop_head"
                      boundingObject USE ball
                      physics Physics {
                      }
                    }
                  ]
                  name "lollipop(11)"
                  contactMaterial "cacao_pickup"
                  boundingObject USE lolipop_group
                  physics USE lollipop_ph
                }
              }
              BallJoint {
                jointParameters BallJointParameters {
                  anchor -0.113802 -0.042415 0
                  springConstant 2
                  dampingConstant 1e-06
                }
                endPoint Solid {
                  translation -0.1693979999999985 -0.06496599999999919 0.0002632050000000228
                  rotation 0.19146832751668996 -0.9636365807320765 0.1863985510484289 1.5977053071793914
                  children [
                    USE lolipop_group
                    Solid {
                      translation 0 0 0.06
                      children [
                        Shape {
                          appearance USE lolipop_base_color
                          geometry USE ball
                        }
                      ]
                      contactMaterial "lolipop_head"
                      boundingObject USE ball
                      physics Physics {
                      }
                    }
                  ]
                  name "lollipop(12)"
                  contactMaterial "cacao_pickup"
                  boundingObject USE lolipop_group
                  physics USE lollipop_ph
                }
              }
              BallJoint {
                jointParameters BallJointParameters {
                  anchor -0.0947202 -0.07136 0
                  springConstant 2
                  dampingConstant 1e-06
                }
                endPoint Solid {
                  translation -0.14108800000000032 -0.10942400000000072 0.0005651400000000807
                  rotation 0.3255564936392626 -0.8900577404821315 0.31907708795391626 1.6633053071793538
                  children [
                    USE lolipop_group
                    Solid {
                      translation 0 0 0.06
                      children [
                        Shape {
                          appearance USE lolipop_base_color
                          geometry USE ball
                        }
                      ]
                      contactMaterial "lolipop_head"
                      boundingObject USE ball
                      physics Physics {
                      }
                    }
                  ]
                  name "lollipop(14)"
                  contactMaterial "cacao_pickup"
                  boundingObject USE lolipop_group
                  physics USE lollipop_ph
                }
              }
              BallJoint {
                jointParameters BallJointParameters {
                  anchor 0.113802 0.042415 0.00149135
                  springConstant 2
                  dampingConstant 1e-06
                }
                endPoint Solid {
                  translation 0.16939800000000133 0.06496600000000105 0.0009650279999999807
                  rotation -0.7041880628811853 -0.13484001204067378 -0.6970920622475304 2.866325307179586
                  children [
                    USE lolipop_group
                    Solid {
                      translation 0 0 0.06
                      children [
                        Shape {
                          appearance USE lolipop_base_color
                          geometry USE ball
                        }
                      ]
                      contactMaterial "lolipop_head"
                      boundingObject USE ball
                      physics Physics {
                      }
                    }
                  ]
                  name "lollipop(13)"
                  contactMaterial "cacao_pickup"
                  boundingObject USE lolipop_group
                  physics USE lollipop_ph
                }
              }
              BallJoint {
                jointParameters BallJointParameters {
                  anchor 0.0947202 0.0713605 0.00320256
                  springConstant 2
                  dampingConstant 1e-06
                }
                endPoint Solid {
                  translation 0.14108800000000055 0.10942399999999922 0.0020722200000000282
                  rotation -0.6940435039274726 -0.24294917639927188 -0.6777014920619489 2.655625307179538
                  children [
                    USE lolipop_group
                    Solid {
                      translation 0 0 0.06
                      children [
                        Shape {
                          appearance USE lolipop_base_color
                          geometry USE ball
                        }
                      ]
                      contactMaterial "lolipop_head"
                      boundingObject USE ball
                      physics Physics {
                      }
                    }
                  ]
                  name "lollipop(15)"
                  contactMaterial "cacao_pickup"
                  boundingObject USE lolipop_group
                  physics USE lollipop_ph
                }
              }
              BallJoint {
                jointParameters BallJointParameters {
                  anchor -0.070822 -0.0947397 7.5131e-08
                  springConstant 2
                  dampingConstant 1e-06
                }
                endPoint Solid {
                  translation -0.1008220000000009 -0.14670000000000227 -7.513130003469627e-08
                  rotation 0.4472137236217806 -0.7745965212991125 0.4472137236217771 1.8234799999998272
                  children [
                    USE lolipop_group
                    Solid {
                      translation 0 0 0.06
                      children [
                        Shape {
                          appearance USE lolipop_base_color
                          geometry USE ball
                        }
                      ]
                      contactMaterial "lolipop_head"
                      boundingObject USE ball
                      physics Physics {
                      }
                    }
                  ]
                  name "lollipop(16)"
                  contactMaterial "cacao_pickup"
                  boundingObject USE lolipop_group
                  physics USE lollipop_ph
                }
              }
              BallJoint {
                jointParameters BallJointParameters {
                  anchor -0.037118 -0.11271 0
                  springConstant 2
                  dampingConstant 1e-06
                }
                endPoint Solid {
                  translation -0.052647199999999665 -0.17066399999999832 2.8933200022689468e-08
                  rotation 0.519988137482549 -0.6776611791705768 0.5199881374825521 1.9504399999997994
                  children [
                    USE lolipop_group
                    Solid {
                      translation 0 0 0.06
                      children [
                        Shape {
                          appearance USE lolipop_base_color
                          geometry USE ball
                        }
                      ]
                      contactMaterial "lolipop_head"
                      boundingObject USE ball
                      physics Physics {
                      }
                    }
                  ]
                  name "lollipop(18)"
                  contactMaterial "cacao_pickup"
                  boundingObject USE lolipop_group
                  physics USE lollipop_ph
                }
              }
              BallJoint {
                jointParameters BallJointParameters {
                  anchor 0.070822 0.0947397 0
                  springConstant 2
                  dampingConstant 1e-06
                }
                endPoint Solid {
                  translation 0.10082199999999891 0.1466999999999986 -3.4544299979170044e-07
                  rotation -0.6546520159230991 -0.3779650091932431 -0.6546550159231763 2.418855307179556
                  children [
                    USE lolipop_group
                    Solid {
                      translation 0 0 0.06
                      children [
                        Shape {
                          appearance USE lolipop_base_color
                          geometry USE ball
                        }
                      ]
                      contactMaterial "lolipop_head"
                      boundingObject USE ball
                      physics Physics {
                      }
                    }
                  ]
                  name "lollipop(17)"
                  contactMaterial "cacao_pickup"
                  boundingObject USE lolipop_group
                  physics USE lollipop_ph
                }
              }
              BallJoint {
                jointParameters BallJointParameters {
                  anchor 0.037118 0.11271 0
                  springConstant 2
                  dampingConstant 1e-06
                }
                endPoint Solid {
                  translation 0.052647199999999894 0.17066399999999848 3.2967199810112965e-08
                  rotation -0.6215153336152235 -0.47690525599185224 -0.6215143336146828 2.2515853071794636
                  children [
                    USE lolipop_group
                    Solid {
                      translation 0 0 0.06
                      children [
                        Shape {
                          appearance USE lolipop_base_color
                          geometry USE ball
                        }
                      ]
                      contactMaterial "lolipop_head"
                      boundingObject USE ball
                      physics Physics {
                      }
                    }
                  ]
                  name "lollipop(19)"
                  contactMaterial "cacao_pickup"
                  boundingObject USE lolipop_group
                  physics USE lollipop_ph
                }
              }
            ]
            name "solid(3)"
            contactMaterial ""
            boundingObject USE disk
            physics Physics {
              density -1
              mass 1
              centerOfMass [
                0.0004964075240797066 0 2.6683962694384078e-09
              ]
              inertiaMatrix [
                0.015474887112992634 0.015695834201723817 0.030518910912255608
                0 -1.1783490361212277e-09 0
              ]
              damping Damping {
                linear 0.715292
                angular 0.715292
              }
            }
          }
          Solid {
            translation 0 0 -0.048
            rotation 0 0 1 -2.3561953071795863
            children [
              DEF disk Group {
                children [
                  Shape {
                    appearance PBRAppearance {
                      baseColor 0.223529 0.223529 0.223529
                      metalness 0
                    }
                    geometry Cylinder {
                      height 0.03048
                      radius 0.1216
                    }
                    castShadows FALSE
                  }
                ]
              }
              BallJoint {
                jointParameters BallJointParameters {
                  anchor 0 0.12 0
                  springConstant 2
                  dampingConstant 1e-06
                }
                endPoint Solid {
                  translation 2.7065292722369164e-17 0.17599999999999752 9.302454639925628e-17
                  rotation -0.9999999999999999 2.1726857555703336e-15 7.55157574728593e-16 1.5707953071789895
                  children [
                    DEF lolipop_group Group {
                      children [
                        Shape {
                          appearance PBRAppearance {
                            baseColor 0.360784 0.360784 0
                            metalness 0
                          }
                          geometry Cylinder {
                            height 0.116
                            radius 0.00325
                            subdivision 3
                          }
                        }
                      ]
                    }
                    Solid {
                      translation 0 0 0.06
                      children [
                        DEF ball Shape {
                          appearance DEF lolipop_base_color PBRAppearance {
                            baseColor 1 1 0
                            roughness 1
                            metalness 0
                          }
                          geometry DEF ball Sphere {
                            radius 0.02
                            subdivision 2
                          }
                        }
                      ]
                      contactMaterial "lolipop_head"
                      boundingObject USE ball
                      physics Physics {
                      }
                    }
                  ]
                  name "lollipop"
                  contactMaterial "cacao_pickup"
                  boundingObject USE lolipop_group
                  physics DEF lollipop_ph Physics {
                    density -1
                    mass 0.1
                    centerOfMass [
                      0 0 0
                    ]
                    inertiaMatrix [
                      5.7e-05 5.7e-05 9.7e-06
                      0 0 0
                    ]
                  }
                }
              }
              BallJoint {
                jointParameters BallJointParameters {
                  anchor 0 -0.12 0
                  springConstant 2
                  dampingConstant 1e-06
                }
                endPoint Solid {
                  translation 1.3168199998395667e-07 -0.1759999999999995 -9.899469982180297e-08
                  rotation -3.3904999553030373e-09 0.7071072811865681 -0.7071062811861736 3.141589999999998
                  children [
                    USE lolipop_group
                    Solid {
                      translation 0 0 0.06
                      children [
                        Shape {
                          appearance USE lolipop_base_color
                          geometry USE ball
                        }
                      ]
                      contactMaterial "lolipop_head"
                      boundingObject USE ball
                      physics Physics {
                      }
                    }
                  ]
                  name "lollipop(1)"
                  contactMaterial "cacao_pickup"
                  boundingObject USE lolipop_group
                  physics USE lollipop_ph
                }
              }
              BallJoint {
                jointParameters BallJointParameters {
                  anchor -0.12 0 0
                  springConstant 2
                  dampingConstant 1e-06
                }
                endPoint Solid {
                  translation -0.17599999999999894 -8.910469999360566e-08 -8.910470003088984e-08
                  rotation -0.5773496025226467 -0.5773516025212769 0.5773496025226442 2.094395307179377
                  children [
                    Solid {
                      translation 0 0 0.06
                      children [
                        Shape {
                          appearance USE lolipop_base_color
                          geometry USE ball
                        }
                      ]
                      contactMaterial "lolipop_head"
                      boundingObject USE ball
                      physics Physics {
                      }
                    }
                    USE lolipop_group
                  ]
                  name "lollipop(2)"
                  contactMaterial "cacao_pickup"
                  boundingObject USE lolipop_group
                  physics USE lollipop_ph
                }
              }
              BallJoint {
                jointParameters BallJointParameters {
                  anchor 0.12 0 0
                  springConstant 2
                  dampingConstant 1e-06
                }
                endPoint Solid {
                  translation 0.176000000000001 1.864567009345991e-17 4.27444588920042e-17
                  rotation -0.5773499358561353 0.5773509358560306 -0.5773499358561343 2.0943899999999376
                  children [
                    USE lolipop_group
                    Solid {
                      translation 0 0 0.06
                      children [
                        Shape {
                          appearance USE lolipop_base_color
                          geometry USE ball
                        }
                      ]
                      contactMaterial "lolipop_head"
                      boundingObject USE ball
                      physics Physics {
                      }
                    }
                  ]
                  name "lollipop(3)"
                  contactMaterial "cacao_pickup"
                  boundingObject USE lolipop_group
                  physics USE lollipop_ph
                }
              }
              BallJoint {
                jointParameters BallJointParameters {
                  anchor 0.11551 -0.0375066 0
                  springConstant 2
                  dampingConstant 1e-06
                }
                endPoint Solid {
                  translation 0.16959999999999817 -0.051999999999999776 1.8285899996776098e-07
                  rotation -0.47690495958779844 0.6215159473336712 -0.6215139473338388 2.251579999999854
                  children [
                    Solid {
                      translation 0 0 0.06
                      children [
                        Shape {
                          appearance USE lolipop_base_color
                          geometry USE ball
                        }
                      ]
                      contactMaterial "lolipop_head"
                      boundingObject USE ball
                      physics Physics {
                      }
                    }
                    USE lolipop_group
                  ]
                  name "lollipop(4)"
                  contactMaterial "cacao_pickup"
                  boundingObject USE lolipop_group
                  physics USE lollipop_ph
                }
              }
              BallJoint {
                jointParameters BallJointParameters {
                  anchor 0.098704 -0.0696 0
                  springConstant 2
                  dampingConstant 1e-06
                }
                endPoint Solid {
                  translation 0.1472000000000005 -0.09760000000000066 -3.3270299092222518e-09
                  rotation -0.3779641520502832 0.6546552633596822 -0.6546522633584761 2.4188499999999893
                  children [
                    Solid {
                      translation 0 0 0.06
                      children [
                        Shape {
                          appearance USE lolipop_base_color
                          geometry USE ball
                        }
                      ]
                      contactMaterial "lolipop_head"
                      boundingObject USE ball
                      physics Physics {
                      }
                    }
                    USE lolipop_group
                  ]
                  name "lollipop(6)"
                  contactMaterial "cacao_pickup"
                  boundingObject USE lolipop_group
                  physics USE lollipop_ph
                }
              }
              BallJoint {
                jointParameters BallJointParameters {
                  anchor -0.11551 0.0375066 0
                  springConstant 2
                  dampingConstant 1e-06
                }
                endPoint Solid {
                  translation -0.16959999999999814 0.051999999999999574 -3.38069999942809e-07
                  rotation -0.6776590404813144 -0.5199930310628315 0.5199860310624062 1.9504453071793915
                  children [
                    USE lolipop_group
                    Solid {
                      translation 0 0 0.06
                      children [
                        Shape {
                          appearance USE lolipop_base_color
                          geometry USE ball
                        }
                      ]
                      contactMaterial "lolipop_head"
                      boundingObject USE ball
                      physics Physics {
                      }
                    }
                  ]
                  name "lollipop(5)"
                  contactMaterial "cacao_pickup"
                  boundingObject USE lolipop_group
                  physics USE lollipop_ph
                }
              }
              BallJoint {
                jointParameters BallJointParameters {
                  anchor -0.098704 0.0696 0
                  springConstant 2
                  dampingConstant 1e-06
                }
                endPoint Solid {
                  translation -0.14719999999999922 0.09759999999999895 1.9606500042707465e-08
                  rotation -0.7745939356444227 -0.44721896284370366 0.4472129628441976 1.8234753071793393
                  children [
                    USE lolipop_group
                    Solid {
                      translation 0 0 0.06
                      children [
                        Shape {
                          appearance USE lolipop_base_color
                          geometry USE ball
                        }
                      ]
                      contactMaterial "lolipop_head"
                      boundingObject USE ball
                      physics Physics {
                      }
                    }
                  ]
                  name "lollipop(7)"
                  contactMaterial "cacao_pickup"
                  boundingObject USE lolipop_group
                  physics USE lollipop_ph
                }
              }
              BallJoint {
                jointParameters BallJointParameters {
                  anchor 0.0733888 -0.097236 0
                  springConstant 2
                  dampingConstant 1e-06
                }
                endPoint Solid {
                  translation 0.10841800000000029 -0.14091599999999926 -0.0008662480000000417
                  rotation 0.46885932512432127 0.8160377347211726 -0.33801382923647266 1.7177799999997823
                  children [
                    USE lolipop_group
                    Solid {
                      translation 0 0 0.06
                      children [
                        Shape {
                          appearance USE lolipop_base_color
                          geometry USE ball
                        }
                      ]
                      contactMaterial "lolipop_head"
                      boundingObject USE ball
                      physics Physics {
                      }
                    }
                  ]
                  name "lollipop(8)"
                  contactMaterial "cacao_pickup"
                  boundingObject USE lolipop_group
                  physics USE lollipop_ph
                }
              }
              BallJoint {
                jointParameters BallJointParameters {
                  anchor -0.0733888 0.097236 0
                  springConstant 2
                  dampingConstant 1e-06
                }
                endPoint Solid {
                  translation -0.10841799999999864 0.14091599999999643 -6.662422349923425e-17
                  rotation -0.6987879380300911 0.27374397572384374 0.6608779413920223 2.4158053071795345
                  children [
                    USE lolipop_group
                    Solid {
                      translation 0 0 0.06
                      children [
                        Shape {
                          appearance USE lolipop_base_color
                          geometry USE ball
                        }
                      ]
                      contactMaterial "lolipop_head"
                      boundingObject USE ball
                      physics Physics {
                      }
                    }
                  ]
                  name "lollipop(9)"
                  contactMaterial "cacao_pickup"
                  boundingObject USE lolipop_group
                  physics USE lollipop_ph
                }
              }
              BallJoint {
                jointParameters BallJointParameters {
                  anchor -0.038562 0.11354 0
                  springConstant 2
                  dampingConstant 1e-06
                }
                endPoint Solid {
                  translation -0.06282479999999879 0.16841599999999712 9.046280000015388e-05
                  rotation -0.9559370020737346 -0.14344101411476526 0.25614277958983867 1.6378353071793776
                  children [
                    USE lolipop_group
                    Solid {
                      translation 0 0 0.06
                      children [
                        Shape {
                          appearance USE lolipop_base_color
                          geometry USE ball
                        }
                      ]
                      contactMaterial "lolipop_head"
                      boundingObject USE ball
                      physics Physics {
                      }
                    }
                  ]
                  name "lollipop(10)"
                  contactMaterial "cacao_pickup"
                  boundingObject USE lolipop_group
                  physics USE lollipop_ph
                }
              }
              BallJoint {
                jointParameters BallJointParameters {
                  anchor 0.038562 -0.11354 0.000301598
                  springConstant 2
                  dampingConstant 1e-06
                }
                endPoint Solid {
                  translation 0.06282479999999922 -0.16841599999999995 0.00012063799999990525
                  rotation -0.18812399565348753 0.6867919841320214 -0.7020869837786256 2.93167
                  children [
                    USE lolipop_group
                    Solid {
                      translation 0 0 0.06
                      children [
                        Shape {
                          appearance USE lolipop_base_color
                          geometry USE ball
                        }
                      ]
                      contactMaterial "lolipop_head"
                      boundingObject USE ball
                      physics Physics {
                      }
                    }
                  ]
                  name "lollipop(11)"
                  contactMaterial "cacao_pickup"
                  boundingObject USE lolipop_group
                  physics USE lollipop_ph
                }
              }
              BallJoint {
                jointParameters BallJointParameters {
                  anchor -0.113802 -0.042415 0
                  springConstant 2
                  dampingConstant 1e-06
                }
                endPoint Solid {
                  translation -0.16939800000000022 -0.06496600000000005 0.0002632050000001066
                  rotation 0.19146832751669426 -0.9636365807320769 0.1863985510484231 1.597705307179385
                  children [
                    USE lolipop_group
                    Solid {
                      translation 0 0 0.06
                      children [
                        Shape {
                          appearance USE lolipop_base_color
                          geometry USE ball
                        }
                      ]
                      contactMaterial "lolipop_head"
                      boundingObject USE ball
                      physics Physics {
                      }
                    }
                  ]
                  name "lollipop(12)"
                  contactMaterial "cacao_pickup"
                  boundingObject USE lolipop_group
                  physics USE lollipop_ph
                }
              }
              BallJoint {
                jointParameters BallJointParameters {
                  anchor -0.0947202 -0.07136 0
                  springConstant 2
                  dampingConstant 1e-06
                }
                endPoint Solid {
                  translation -0.14108799999999688 -0.10942399999999725 0.0005651399999999808
                  rotation 0.3255564936392589 -0.8900577404821323 0.3190770879539181 1.66330530717937
                  children [
                    USE lolipop_group
                    Solid {
                      translation 0 0 0.06
                      children [
                        Shape {
                          appearance USE lolipop_base_color
                          geometry USE ball
                        }
                      ]
                      contactMaterial "lolipop_head"
                      boundingObject USE ball
                      physics Physics {
                      }
                    }
                  ]
                  name "lollipop(14)"
                  contactMaterial "cacao_pickup"
                  boundingObject USE lolipop_group
                  physics USE lollipop_ph
                }
              }
              BallJoint {
                jointParameters BallJointParameters {
                  anchor 0.113802 0.042415 0.00149135
                  springConstant 2
                  dampingConstant 1e-06
                }
                endPoint Solid {
                  translation 0.16939799999999877 0.06496599999999945 0.0009650280000000268
                  rotation -0.7041880628811853 -0.13484001204067467 -0.6970920622475303 2.8663253071795864
                  children [
                    USE lolipop_group
                    Solid {
                      translation 0 0 0.06
                      children [
                        Shape {
                          appearance USE lolipop_base_color
                          geometry USE ball
                        }
                      ]
                      contactMaterial "lolipop_head"
                      boundingObject USE ball
                      physics Physics {
                      }
                    }
                  ]
                  name "lollipop(13)"
                  contactMaterial "cacao_pickup"
                  boundingObject USE lolipop_group
                  physics USE lollipop_ph
                }
              }
              BallJoint {
                jointParameters BallJointParameters {
                  anchor 0.0947202 0.0713605 0.00320256
                  springConstant 2
                  dampingConstant 1e-06
                }
                endPoint Solid {
                  translation 0.1410879999999998 0.10942399999999952 0.002072220000000043
                  rotation -0.6940435039274752 -0.24294917639926866 -0.6777014920619476 2.6556253071795357
                  children [
                    USE lolipop_group
                    Solid {
                      translation 0 0 0.06
                      children [
                        Shape {
                          appearance USE lolipop_base_color
                          geometry USE ball
                        }
                      ]
                      contactMaterial "lolipop_head"
                      boundingObject USE ball
                      physics Physics {
                      }
                    }
                  ]
                  name "lollipop(15)"
                  contactMaterial "cacao_pickup"
                  boundingObject USE lolipop_group
                  physics USE lollipop_ph
                }
              }
              BallJoint {
                jointParameters BallJointParameters {
                  anchor -0.070822 -0.0947397 7.5131e-08
                  springConstant 2
                  dampingConstant 1e-06
                }
                endPoint Solid {
                  translation -0.100821999999999 -0.14669999999999914 -7.513130039980135e-08
                  rotation 0.44721372362178 -0.7745965212991139 0.4472137236217755 1.8234799999998224
                  children [
                    USE lolipop_group
                    Solid {
                      translation 0 0 0.06
                      children [
                        Shape {
                          appearance USE lolipop_base_color
                          geometry USE ball
                        }
                      ]
                      contactMaterial "lolipop_head"
                      boundingObject USE ball
                      physics Physics {
                      }
                    }
                  ]
                  name "lollipop(16)"
                  contactMaterial "cacao_pickup"
                  boundingObject USE lolipop_group
                  physics USE lollipop_ph
                }
              }
              BallJoint {
                jointParameters BallJointParameters {
                  anchor -0.037118 -0.11271 0
                  springConstant 2
                  dampingConstant 1e-06
                }
                endPoint Solid {
                  translation -0.052647199999999984 -0.1706639999999998 2.893319985721311e-08
                  rotation 0.519988137482547 -0.6776611791705883 0.5199881374825384 1.950439999999819
                  children [
                    USE lolipop_group
                    Solid {
                      translation 0 0 0.06
                      children [
                        Shape {
                          appearance USE lolipop_base_color
                          geometry USE ball
                        }
                      ]
                      contactMaterial "lolipop_head"
                      boundingObject USE ball
                      physics Physics {
                      }
                    }
                  ]
                  name "lollipop(18)"
                  contactMaterial "cacao_pickup"
                  boundingObject USE lolipop_group
                  physics USE lollipop_ph
                }
              }
              BallJoint {
                jointParameters BallJointParameters {
                  anchor 0.070822 0.0947397 0
                  springConstant 2
                  dampingConstant 1e-06
                }
                endPoint Solid {
                  translation 0.1008219999999974 0.14669999999999628 -3.4544299997144083e-07
                  rotation -0.6546520159231003 -0.37796500919324516 -0.6546550159231735 2.418855307179558
                  children [
                    USE lolipop_group
                    Solid {
                      translation 0 0 0.06
                      children [
                        Shape {
                          appearance USE lolipop_base_color
                          geometry USE ball
                        }
                      ]
                      contactMaterial "lolipop_head"
                      boundingObject USE ball
                      physics Physics {
                      }
                    }
                  ]
                  name "lollipop(17)"
                  contactMaterial "cacao_pickup"
                  boundingObject USE lolipop_group
                  physics USE lollipop_ph
                }
              }
              BallJoint {
                jointParameters BallJointParameters {
                  anchor 0.037118 0.11271 0
                  springConstant 2
                  dampingConstant 1e-06
                }
                endPoint Solid {
                  translation 0.05264720000000042 0.17066399999999968 3.2967199874948255e-08
                  rotation -0.6215153336152233 -0.4769052559918539 -0.6215143336146817 2.2515853071794587
                  children [
                    USE lolipop_group
                    Solid {
                      translation 0 0 0.06
                      children [
                        Shape {
                          appearance USE lolipop_base_color
                          geometry USE ball
                        }
                      ]
                      contactMaterial "lolipop_head"
                      boundingObject USE ball
                      physics Physics {
                      }
                    }
                  ]
                  name "lollipop(19)"
                  contactMaterial "cacao_pickup"
                  boundingObject USE lolipop_group
                  physics USE lollipop_ph
                }
              }
            ]
            name "solid(1)"
            contactMaterial ""
            boundingObject USE disk
            physics Physics {
              density -1
              mass 1
              centerOfMass [
                0.0004964075240797066 0 2.6683962694384078e-09
              ]
              inertiaMatrix [
                0.015474887112992634 0.015695834201723817 0.030518910912255608
                0 -1.1783490361212277e-09 0
              ]
              damping Damping {
                linear 0.715292
                angular 0.715292
              }
            }
          }
          Solid {
            translation 0 0 0.132
            rotation 0 0 1 -0.785395307179586
            children [
              DEF disk Group {
                children [
                  Shape {
                    appearance PBRAppearance {
                      baseColor 0.223529 0.223529 0.223529
                      metalness 0
                    }
                    geometry Cylinder {
                      height 0.03048
                      radius 0.1216
                    }
                    castShadows FALSE
                  }
                ]
              }
              BallJoint {
                jointParameters BallJointParameters {
                  anchor 0 0.12 0
                  springConstant 2
                  dampingConstant 1e-06
                }
                endPoint Solid {
                  translation 3.0985725006635225e-17 0.17599999999999888 -2.8514517136368767e-17
                  rotation -0.9999999999999999 5.4818287574838035e-16 1.2141312247190098e-15 1.5707953071789915
                  children [
                    DEF lolipop_group Group {
                      children [
                        Shape {
                          appearance PBRAppearance {
                            baseColor 0.360784 0.360784 0
                            metalness 0
                          }
                          geometry Cylinder {
                            height 0.116
                            radius 0.00325
                            subdivision 3
                          }
                        }
                      ]
                    }
                    Solid {
                      translation 0 0 0.06
                      children [
                        DEF ball Shape {
                          appearance DEF lolipop_base_color PBRAppearance {
                            baseColor 1 1 0
                            roughness 1
                            metalness 0
                          }
                          geometry DEF ball Sphere {
                            radius 0.02
                            subdivision 2
                          }
                        }
                      ]
                      contactMaterial "lolipop_head"
                      boundingObject USE ball
                      physics Physics {
                      }
                    }
                  ]
                  name "lollipop"
                  contactMaterial "cacao_pickup"
                  boundingObject USE lolipop_group
                  physics DEF lollipop_ph Physics {
                    density -1
                    mass 0.1
                    centerOfMass [
                      0 0 0
                    ]
                    inertiaMatrix [
                      5.7e-05 5.7e-05 9.7e-06
                      0 0 0
                    ]
                  }
                }
              }
              BallJoint {
                jointParameters BallJointParameters {
                  anchor 0 -0.12 0
                  springConstant 2
                  dampingConstant 1e-06
                }
                endPoint Solid {
                  translation 1.316819999905203e-07 -0.1759999999999984 -9.899469979065927e-08
                  rotation -3.3905016912072772e-09 0.707107281186571 -0.7071062811861705 3.14159
                  children [
                    USE lolipop_group
                    Solid {
                      translation 0 0 0.06
                      children [
                        Shape {
                          appearance USE lolipop_base_color
                          geometry USE ball
                        }
                      ]
                      contactMaterial "lolipop_head"
                      boundingObject USE ball
                      physics Physics {
                      }
                    }
                  ]
                  name "lollipop(1)"
                  contactMaterial "cacao_pickup"
                  boundingObject USE lolipop_group
                  physics USE lollipop_ph
                }
              }
              BallJoint {
                jointParameters BallJointParameters {
                  anchor -0.12 0 0
                  springConstant 2
                  dampingConstant 1e-06
                }
                endPoint Solid {
                  translation -0.1760000000000002 -8.910469992408741e-08 -8.910469997430761e-08
                  rotation -0.5773496025226328 -0.5773516025212888 0.5773496025226463 2.09439530717936
                  children [
                    Solid {
                      translation 0 0 0.06
                      children [
                        Shape {
                          appearance USE lolipop_base_color
                          geometry USE ball
                        }
                      ]
                      contactMaterial "lolipop_head"
                      boundingObject USE ball
                      physics Physics {
                      }
                    }
                    USE lolipop_group
                  ]
                  name "lollipop(2)"
                  contactMaterial "cacao_pickup"
                  boundingObject USE lolipop_group
                  physics USE lollipop_ph
                }
              }
              BallJoint {
                jointParameters BallJointParameters {
                  anchor 0.12 0 0
                  springConstant 2
                  dampingConstant 1e-06
                }
                endPoint Solid {
                  translation 0.17599999999999966 1.3900086399930384e-17 1.9135526452213812e-17
                  rotation -0.5773499358561436 0.5773509358560222 -0.5773499358561344 2.0943899999999243
                  children [
                    USE lolipop_group
                    Solid {
                      translation 0 0 0.06
                      children [
                        Shape {
                          appearance USE lolipop_base_color
                          geometry USE ball
                        }
                      ]
                      contactMaterial "lolipop_head"
                      boundingObject USE ball
                      physics Physics {
                      }
                    }
                  ]
                  name "lollipop(3)"
                  contactMaterial "cacao_pickup"
                  boundingObject USE lolipop_group
                  physics USE lollipop_ph
                }
              }
              BallJoint {
                jointParameters BallJointParameters {
                  anchor 0.11551 -0.0375066 0
                  springConstant 2
                  dampingConstant 1e-06
                }
                endPoint Solid {
                  translation 0.169599999999998 -0.05199999999999956 1.8285900009809902e-07
                  rotation -0.47690495958780105 0.6215159473336667 -0.6215139473338414 2.251579999999867
                  children [
                    Solid {
                      translation 0 0 0.06
                      children [
                        Shape {
                          appearance USE lolipop_base_color
                          geometry USE ball
                        }
                      ]
                      contactMaterial "lolipop_head"
                      boundingObject USE ball
                      physics Physics {
                      }
                    }
                    USE lolipop_group
                  ]
                  name "lollipop(4)"
                  contactMaterial "cacao_pickup"
                  boundingObject USE lolipop_group
                  physics USE lollipop_ph
                }
              }
              BallJoint {
                jointParameters BallJointParameters {
                  anchor 0.098704 -0.0696 0
                  springConstant 2
                  dampingConstant 1e-06
                }
                endPoint Solid {
                  translation 0.14719999999999853 -0.09759999999999909 -3.3270301878418813e-09
                  rotation -0.3779641520502897 0.6546552633596817 -0.6546522633584729 2.4188499999999755
                  children [
                    Solid {
                      translation 0 0 0.06
                      children [
                        Shape {
                          appearance USE lolipop_base_color
                          geometry USE ball
                        }
                      ]
                      contactMaterial "lolipop_head"
                      boundingObject USE ball
                      physics Physics {
                      }
                    }
                    USE lolipop_group
                  ]
                  name "lollipop(6)"
                  contactMaterial "cacao_pickup"
                  boundingObject USE lolipop_group
                  physics USE lollipop_ph
                }
              }
              BallJoint {
                jointParameters BallJointParameters {
                  anchor -0.11551 0.0375066 0
                  springConstant 2
                  dampingConstant 1e-06
                }
                endPoint Solid {
                  translation -0.16959999999999614 0.05199999999999947 -3.380699999284365e-07
                  rotation -0.6776590404813156 -0.5199930310628281 0.5199860310624076 1.9504453071793875
                  children [
                    USE lolipop_group
                    Solid {
                      translation 0 0 0.06
                      children [
                        Shape {
                          appearance USE lolipop_base_color
                          geometry USE ball
                        }
                      ]
                      contactMaterial "lolipop_head"
                      boundingObject USE ball
                      physics Physics {
                      }
                    }
                  ]
                  name "lollipop(5)"
                  contactMaterial "cacao_pickup"
                  boundingObject USE lolipop_group
                  physics USE lollipop_ph
                }
              }
              BallJoint {
                jointParameters BallJointParameters {
                  anchor -0.098704 0.0696 0
                  springConstant 2
                  dampingConstant 1e-06
                }
                endPoint Solid {
                  translation -0.14720000000000089 0.0976000000000006 1.96064999951652e-08
                  rotation -0.7745939356444252 -0.4472189628437024 0.447212962844195 1.8234753071793255
                  children [
                    USE lolipop_group
                    Solid {
                      translation 0 0 0.06
                      children [
                        Shape {
                          appearance USE lolipop_base_color
                          geometry USE ball
                        }
                      ]
                      contactMaterial "lolipop_head"
                      boundingObject USE ball
                      physics Physics {
                      }
                    }
                  ]
                  name "lollipop(7)"
                  contactMaterial "cacao_pickup"
                  boundingObject USE lolipop_group
                  physics USE lollipop_ph
                }
              }
              BallJoint {
                jointParameters BallJointParameters {
                  anchor 0.0733888 -0.097236 0
                  springConstant 2
                  dampingConstant 1e-06
                }
                endPoint Solid {
                  translation 0.10841799999999897 -0.1409159999999989 -0.0008662479999999562
                  rotation 0.46885932512431694 0.8160377347211751 -0.33801382923647255 1.717779999999814
                  children [
                    USE lolipop_group
                    Solid {
                      translation 0 0 0.06
                      children [
                        Shape {
                          appearance USE lolipop_base_color
                          geometry USE ball
                        }
                      ]
                      contactMaterial "lolipop_head"
                      boundingObject USE ball
                      physics Physics {
                      }
                    }
                  ]
                  name "lollipop(8)"
                  contactMaterial "cacao_pickup"
                  boundingObject USE lolipop_group
                  physics USE lollipop_ph
                }
              }
              BallJoint {
                jointParameters BallJointParameters {
                  anchor -0.0733888 0.097236 0
                  springConstant 2
                  dampingConstant 1e-06
                }
                endPoint Solid {
                  translation -0.10841800000000032 0.1409160000000014 1.1958749962515114e-16
                  rotation -0.6987879380300928 0.27374397572384257 0.660877941392021 2.415805307179545
                  children [
                    USE lolipop_group
                    Solid {
                      translation 0 0 0.06
                      children [
                        Shape {
                          appearance USE lolipop_base_color
                          geometry USE ball
                        }
                      ]
                      contactMaterial "lolipop_head"
                      boundingObject USE ball
                      physics Physics {
                      }
                    }
                  ]
                  name "lollipop(9)"
                  contactMaterial "cacao_pickup"
                  boundingObject USE lolipop_group
                  physics USE lollipop_ph
                }
              }
              BallJoint {
                jointParameters BallJointParameters {
                  anchor -0.038562 0.11354 0
                  springConstant 2
                  dampingConstant 1e-06
                }
                endPoint Solid {
                  translation -0.06282479999999944 0.1684159999999981 9.046280000012206e-05
                  rotation -0.9559370020737337 -0.14344101411476523 0.25614277958984194 1.6378353071793814
                  children [
                    USE lolipop_group
                    Solid {
                      translation 0 0 0.06
                      children [
                        Shape {
                          appearance USE lolipop_base_color
                          geometry USE ball
                        }
                      ]
                      contactMaterial "lolipop_head"
                      boundingObject USE ball
                      physics Physics {
                      }
                    }
                  ]
                  name "lollipop(10)"
                  contactMaterial "cacao_pickup"
                  boundingObject USE lolipop_group
                  physics USE lollipop_ph
                }
              }
              BallJoint {
                jointParameters BallJointParameters {
                  anchor 0.038562 -0.11354 0.000301598
                  springConstant 2
                  dampingConstant 1e-06
                }
                endPoint Solid {
                  translation 0.06282479999999986 -0.1684159999999996 0.00012063800000015074
                  rotation -0.18812399565348312 0.6867919841320227 -0.7020869837786254 2.9316699999999996
                  children [
                    USE lolipop_group
                    Solid {
                      translation 0 0 0.06
                      children [
                        Shape {
                          appearance USE lolipop_base_color
                          geometry USE ball
                        }
                      ]
                      contactMaterial "lolipop_head"
                      boundingObject USE ball
                      physics Physics {
                      }
                    }
                  ]
                  name "lollipop(11)"
                  contactMaterial "cacao_pickup"
                  boundingObject USE lolipop_group
                  physics USE lollipop_ph
                }
              }
              BallJoint {
                jointParameters BallJointParameters {
                  anchor -0.113802 -0.042415 0
                  springConstant 2
                  dampingConstant 1e-06
                }
                endPoint Solid {
                  translation -0.16939799999999852 -0.06496599999999925 0.0002632050000000097
                  rotation 0.19146832751669723 -0.9636365807320755 0.1863985510484273 1.5977053071793732
                  children [
                    USE lolipop_group
                    Solid {
                      translation 0 0 0.06
                      children [
                        Shape {
                          appearance USE lolipop_base_color
                          geometry USE ball
                        }
                      ]
                      contactMaterial "lolipop_head"
                      boundingObject USE ball
                      physics Physics {
                      }
                    }
                  ]
                  name "lollipop(12)"
                  contactMaterial "cacao_pickup"
                  boundingObject USE lolipop_group
                  physics USE lollipop_ph
                }
              }
              BallJoint {
                jointParameters BallJointParameters {
                  anchor -0.0947202 -0.07136 0
                  springConstant 2
                  dampingConstant 1e-06
                }
                endPoint Solid {
                  translation -0.14108799999999824 -0.10942399999999794 0.0005651399999998387
                  rotation 0.3255564936392605 -0.8900577404821335 0.3190770879539135 1.663305307179398
                  children [
                    USE lolipop_group
                    Solid {
                      translation 0 0 0.06
                      children [
                        Shape {
                          appearance USE lolipop_base_color
                          geometry USE ball
                        }
                      ]
                      contactMaterial "lolipop_head"
                      boundingObject USE ball
                      physics Physics {
                      }
                    }
                  ]
                  name "lollipop(14)"
                  contactMaterial "cacao_pickup"
                  boundingObject USE lolipop_group
                  physics USE lollipop_ph
                }
              }
              BallJoint {
                jointParameters BallJointParameters {
                  anchor 0.113802 0.042415 0.00149135
                  springConstant 2
                  dampingConstant 1e-06
                }
                endPoint Solid {
                  translation 0.16939800000000035 0.06496599999999997 0.0009650279999998692
                  rotation -0.7041880628811753 -0.13484001204067425 -0.6970920622475403 2.8663253071795807
                  children [
                    USE lolipop_group
                    Solid {
                      translation 0 0 0.06
                      children [
                        Shape {
                          appearance USE lolipop_base_color
                          geometry USE ball
                        }
                      ]
                      contactMaterial "lolipop_head"
                      boundingObject USE ball
                      physics Physics {
                      }
                    }
                  ]
                  name "lollipop(13)"
                  contactMaterial "cacao_pickup"
                  boundingObject USE lolipop_group
                  physics USE lollipop_ph
                }
              }
              BallJoint {
                jointParameters BallJointParameters {
                  anchor 0.0947202 0.0713605 0.00320256
                  springConstant 2
                  dampingConstant 1e-06
                }
                endPoint Solid {
                  translation 0.14108799999999852 0.10942399999999942 0.002072219999999949
                  rotation -0.6940435039274649 -0.2429491763992752 -0.6777014920619555 2.6556253071795344
                  children [
                    USE lolipop_group
                    Solid {
                      translation 0 0 0.06
                      children [
                        Shape {
                          appearance USE lolipop_base_color
                          geometry USE ball
                        }
                      ]
                      contactMaterial "lolipop_head"
                      boundingObject USE ball
                      physics Physics {
                      }
                    }
                  ]
                  name "lollipop(15)"
                  contactMaterial "cacao_pickup"
                  boundingObject USE lolipop_group
                  physics USE lollipop_ph
                }
              }
              BallJoint {
                jointParameters BallJointParameters {
                  anchor -0.070822 -0.0947397 7.5131e-08
                  springConstant 2
                  dampingConstant 1e-06
                }
                endPoint Solid {
                  translation -0.10082199999999908 -0.14669999999999944 -7.513129998775032e-08
                  rotation 0.44721372362177936 -0.7745965212991119 0.447213723621779 1.8234799999998472
                  children [
                    USE lolipop_group
                    Solid {
                      translation 0 0 0.06
                      children [
                        Shape {
                          appearance USE lolipop_base_color
                          geometry USE ball
                        }
                      ]
                      contactMaterial "lolipop_head"
                      boundingObject USE ball
                      physics Physics {
                      }
                    }
                  ]
                  name "lollipop(16)"
                  contactMaterial "cacao_pickup"
                  boundingObject USE lolipop_group
                  physics USE lollipop_ph
                }
              }
              BallJoint {
                jointParameters BallJointParameters {
                  anchor -0.037118 -0.11271 0
                  springConstant 2
                  dampingConstant 1e-06
                }
                endPoint Solid {
                  translation -0.052647200000000366 -0.1706640000000023 2.893320007879693e-08
                  rotation 0.5199881374825417 -0.6776611791705873 0.5199881374825457 1.9504399999998283
                  children [
                    USE lolipop_group
                    Solid {
                      translation 0 0 0.06
                      children [
                        Shape {
                          appearance USE lolipop_base_color
                          geometry USE ball
                        }
                      ]
                      contactMaterial "lolipop_head"
                      boundingObject USE ball
                      physics Physics {
                      }
                    }
                  ]
                  name "lollipop(18)"
                  contactMaterial "cacao_pickup"
                  boundingObject USE lolipop_group
                  physics USE lollipop_ph
                }
              }
              BallJoint {
                jointParameters BallJointParameters {
                  anchor 0.070822 0.0947397 0
                  springConstant 2
                  dampingConstant 1e-06
                }
                endPoint Solid {
                  translation 0.10082199999999805 0.146699999999998 -3.4544300003835644e-07
                  rotation -0.6546520159231006 -0.3779650091932408 -0.6546550159231759 2.4188553071795535
                  children [
                    USE lolipop_group
                    Solid {
                      translation 0 0 0.06
                      children [
                        Shape {
                          appearance USE lolipop_base_color
                          geometry USE ball
                        }
                      ]
                      contactMaterial "lolipop_head"
                      boundingObject USE ball
                      physics Physics {
                      }
                    }
                  ]
                  name "lollipop(17)"
                  contactMaterial "cacao_pickup"
                  boundingObject USE lolipop_group
                  physics USE lollipop_ph
                }
              }
              BallJoint {
                jointParameters BallJointParameters {
                  anchor 0.037118 0.11271 0
                  springConstant 2
                  dampingConstant 1e-06
                }
                endPoint Solid {
                  translation 0.052647199999998825 0.17066399999999654 3.296720013147049e-08
                  rotation -0.6215153336152245 -0.4769052559918495 -0.6215143336146838 2.2515853071794645
                  children [
                    USE lolipop_group
                    Solid {
                      translation 0 0 0.06
                      children [
                        Shape {
                          appearance USE lolipop_base_color
                          geometry USE ball
                        }
                      ]
                      contactMaterial "lolipop_head"
                      boundingObject USE ball
                      physics Physics {
                      }
                    }
                  ]
                  name "lollipop(19)"
                  contactMaterial "cacao_pickup"
                  boundingObject USE lolipop_group
                  physics USE lollipop_ph
                }
              }
            ]
            name "solid(2)"
            contactMaterial ""
            boundingObject USE disk
            physics Physics {
              density -1
              mass 1
              centerOfMass [
                0.0004964075240797066 0 2.6683962694384078e-09
              ]
              inertiaMatrix [
                0.015474887112992634 0.015695834201723817 0.030518910912255608
                0 -1.1783490361212277e-09 0
              ]
              damping Damping {
                linear 0.715292
                angular 0.715292
              }
            }
          }
        ]
        name "disks"
        boundingObject USE disk_holder
        physics Physics {
          density -1
          mass 5
        }
      }
    }
    HingeJoint {
      jointParameters HingeJointParameters {
        axis -1 0 0
        anchor 0 0.53 0.25
      }
      device [
        DEF containerSensor PositionSensor {
          name "containerSensor"
        }
        RotationalMotor {
          name "container"
        }
      ]
      endPoint DEF container Solid {
        translation -0.010007488764314591 0.49652423647972493 0.1999584565979074
        rotation -0.9999999980644502 -6.221781299872667e-05 -2.0794492360549987e-07 0.017785464817914647
        children [
          DEF container Group {
            children [
              Transform {
                translation 0.28 1.40785e-07 0.1
                rotation 1 0 0 4.692820414042842e-06
                children [
                  DEF container_side Shape {
                    appearance DEF container_apperarance PBRAppearance {
                      baseColor 1 0.666667 0.498039
                      roughness 1
                      metalness 0
                    }
                    geometry Box {
                      size 0.016 0.4 0.2
                    }
                  }
                ]
              }
              Transform {
                translation -0.27 0 0.1
                rotation 0 1 0 0
                children [
                  USE container_side
                ]
              }
              Transform {
                translation 0 -0.2 0.03
                children [
                  Shape {
                    appearance USE container_apperarance
                    geometry Box {
                      size 0.56 0.0016 0.072
                    }
                  }
                ]
              }
              Transform {
                translation 0 0.19 0.1
                children [
                  Shape {
                    appearance USE container_apperarance
                    geometry Box {
                      size 0.56 0.016 0.2
                    }
                  }
                ]
              }
              Shape {
                appearance USE container_apperarance
                geometry Box {
                  size 0.56 0.4 0.016
                }
              }
            ]
          }
          DEF container_bottom_sensor TouchSensor {
            translation 0 0 0.01
            children [
              DEF container_bottom Shape {
                appearance USE container_apperarance
                geometry Box {
                  size 0.51 0.33 0.001
                }
              }
            ]
            name "container_bottom_sensor"
            boundingObject USE container_bottom
          }
        ]
        name "solid(5)"
        boundingObject USE container
        physics Physics {
          density -1
          mass 1
        }
        recognitionColors [
          1 0 0
        ]
      }
    }
    Solid {
      translation 0 -0.676837 0.961325
      rotation 1 0 0 -0.523595307179586
      children [
        Transform {
          translation 0 0 -0.17
          children [
            Shape {
              appearance PBRAppearance {
                baseColor 0.239216 0.239216 0.239216
                roughness 1
                metalness 0
              }
              geometry Capsule {
                height 0.46
                radius 0.05
              }
            }
          ]
        }
        Camera {
          translation 5.18889e-08 0.07 0.05
          rotation -3.69431e-07 -3.88407e-07 -1 -1.5708053071795867
          children [
            Shape {
              appearance PBRAppearance {
                baseColor 0.666667 0 0
              }
              geometry Sphere {
                radius 0.03
                subdivision 2
              }
            }
            Transform {
              translation -0.02 0 7.34639e-08
              rotation 0 1 0 1.5708
              children [
                Shape {
                  appearance PBRAppearance {
                    baseColor 0 0 0
                    roughness 1
                    metalness 0
                  }
                  geometry Cylinder {
                    height 0.05
                    radius 0.05
                  }
                }
              ]
            }
          ]
          name "CAM"
          fieldOfView 1
          width 640
          height 640
          recognition DEF recog Recognition {
            maxObjects 9
            frameThickness 3
          }
        }
      ]
      name "cam"
    }
    Solid {
      translation 0.01 -0.0682711 0.285036
      rotation 1 0 0 -0.2618053071795865
      children [
        DEF separator Group {
          children [
            Transform {
              translation -0.198 0.215389 0.0950767
              rotation -1 0 0 0.26179530717958593
              children [
                Shape {
                  appearance DEF separator_apperance PBRAppearance {
                    baseColor 1 1 0.498039
                    roughness 1
                    metalness 0
                  }
                  geometry DEF separator_stick Box {
                    size 0.016 0.256 0.016
                  }
                }
              ]
            }
            Transform {
              translation -0.08 0.215389 0.0950766
              rotation -1 0 0 0.26179530717958593
              children [
                Shape {
                  appearance USE separator_apperance
                  geometry USE separator_stick
                }
              ]
            }
            Transform {
              translation -0.11 0.215389 0.0950766
              rotation -1 0 0 0.26179530717958593
              children [
                Shape {
                  appearance USE separator_apperance
                  geometry USE separator_stick
                }
              ]
            }
            Transform {
              translation -0.18 0.215389 0.0950766
              rotation -1 0 0 0.26179530717958593
              children [
                Shape {
                  appearance USE separator_apperance
                  geometry USE separator_stick
                }
              ]
            }
            Transform {
              translation 0.1 0.215389 0.0950766
              rotation -1 0 0 0.26179530717958593
              children [
                Shape {
                  appearance USE separator_apperance
                  geometry USE separator_stick
                }
              ]
            }
            Transform {
              translation 0.2 0.215389 0.0950766
              rotation -1 0 0 0.26179530717958593
              children [
                Shape {
                  appearance USE separator_apperance
                  geometry USE separator_stick
                }
              ]
            }
            Transform {
              translation 0.17 0.215389 0.0950767
              rotation -1 0 0 0.26179530717958593
              children [
                Shape {
                  appearance USE separator_apperance
                  geometry USE separator_stick
                }
              ]
            }
            Transform {
              translation 0 0.34 0.07
              rotation 0 1 0 0
              children [
                Shape {
                  appearance DEF separator_apperance PBRAppearance {
                    baseColor 1 1 0.498039
                    roughness 1
                    metalness 0
                  }
                  geometry Box {
                    size 0.58 0.016 0.016
                  }
                }
              ]
            }
            Transform {
              translation -0.015 0.211673 0.0961306
              rotation 1 0 0 -0.261795307179586
              children [
                Shape {
                  appearance USE separator_apperance
                  geometry USE separator_stick
                }
              ]
            }
            Transform {
              translation 0.01 0.214389 0.0950767
              rotation -1 0 0 0.26179530717958593
              children [
                Shape {
                  appearance USE separator_apperance
                  geometry USE separator_stick
                }
              ]
            }
            Transform {
              translation 0.074 0.211675 0.0961257
              rotation -1 0 0 0.26179530717958593
              children [
                Shape {
                  appearance USE separator_apperance
                  geometry USE separator_stick
                }
              ]
            }
          ]
        }
      ]
      name "separator(1)"
      contactMaterial "separator"
      boundingObject USE separator
      physics Physics {
        density -1
        mass 1
        centerOfMass [
          0 0 0
        ]
      }
    }
    Solid {
      translation 0.299201 0.284349 0.14
      rotation 0 0 1 -0.785395307179586
      children [
        DEF guide Shape {
          appearance USE frame
          geometry Box {
            size 0.01 0.35 0.18
          }
        }
      ]
      contactMaterial "guide"
      boundingObject USE guide
      physics Physics {
        density -1
        mass 0.5
      }
    }
    Solid {
      translation -0.301836 0.291419 0.15
      rotation 0 0 1 0.785401
      children [
        USE guide
      ]
      name "solid(1)"
      contactMaterial "guide"
      boundingObject USE guide
      physics Physics {
        density -1
        mass 0.5
      }
    }
    DEF body_bumper_sensor TouchSensor {
      translation 0 -1 0.26
      children [
        DEF body_bumpers Group {
          children [
            Shape {
              appearance PBRAppearance {
                baseColor 0 0.666667 0.498039
                roughness 1
                metalness 0
              }
              geometry DEF back Box {
                size 0.82 0.04 0.14
              }
            }
            Transform {
              translation -0.37 0.056 0
              rotation 0 1 0 0
              children [
                Shape {
                  appearance PBRAppearance {
                    baseColor 0 0.666667 0.498039
                    roughness 1
                    metalness 0
                  }
                  geometry DEF back Box {
                    size 0.08 0.07 0.14
                  }
                }
              ]
            }
            Transform {
              translation 0.37 0.056 0
              rotation 0 1 0 0
              children [
                Shape {
                  appearance PBRAppearance {
                    baseColor 0 0.666667 0.498039
                    roughness 1
                    metalness 0
                  }
                  geometry DEF back Box {
                    size 0.08 0.07 0.14
                  }
                }
              ]
            }
            Transform {
              translation -0.385 1.543 -0.0168
              rotation 0 1 0 0
              children [
                Shape {
                  appearance USE frame
                  geometry DEF back Box {
                    size 0.105 0.35 0.029
                  }
                }
              ]
            }
            Transform {
              translation 0.375 1.543 -0.0168
              rotation 0 1 0 0
              children [
                Shape {
                  appearance USE frame
                  geometry DEF back Box {
                    size 0.105 0.35 0.029
                  }
                }
              ]
            }
            Transform {
              translation 0.418 0.682 -0.0168
              rotation 0 1 0 0
              children [
                Shape {
                  appearance USE frame
                  geometry DEF back Box {
                    size 0.001 1.36 0.03
                  }
                }
              ]
            }
            Transform {
              translation -0.432 0.682 -0.0168
              rotation 0 1 0 0
              children [
                Shape {
                  appearance USE frame
                  geometry DEF back Box {
                    size 0.001 1.36 0.03
                  }
                }
              ]
            }
          ]
        }
      ]
      name "body_bumper_sensor"
      boundingObject USE body_bumpers
      physics Physics {
        density -1
        mass 1
      }
    }
    DEF gps GPS {
      translation 0 -0.59 0
    }
    DEF lidar Lidar {
      translation 7.34642e-08 -0.43 0.66
      rotation 0 0 1 1.5708
      horizontalResolution 12
      fieldOfView 0.8
      verticalFieldOfView 0.1
      numberOfLayers 1
      maxRange 3
    }
    DEF lidar2 Lidar {
      translation 2.06013e-07 -0.56 0.66
      rotation 0 0 1 -1.5707953071795862
      name "lidar2"
      horizontalResolution 36
      fieldOfView 5.5
      verticalFieldOfView 0.1
      numberOfLayers 1
      maxRange 3
    }
  ]
  name "cacaobot"
  boundingObject USE Body
  physics Physics {
    density -1
    mass 30
    centerOfMass [
      0 -0.0125 0
    ]
  }
  controller "cacaobot"
  supervisor TRUE
}
DEF collection_area Solid {
  translation 1.29 4.49 -0.04
  children [
    Shape {
      geometry DEF gatherarea Box {
        size 2 2 0.081
      }
    }
  ]
  name "collection_area"
  model "collection_area"
  contactMaterial "collection"
  recognitionColors [
    0 0 1
  ]
}
DEF cacao0 Solid {
  translation -3.46624 2.68391 0.0584282
  rotation 0.7070992811436049 7.252082883437699e-07 -0.7071142811495689 -3.1415853071795863
  scale 1.1 1.1 1.1
  children [
    DEF ugly_cacao Group {
      children [
        Transform {
          translation -0.02 0 0
          children [
            Shape {
              appearance DEF cacao1 PBRAppearance {
                baseColor 1 0.333333 0
                metalness 0
              }
              geometry Cylinder {
                height 0.15
                radius 0.03
              }
            }
          ]
        }
        Transform {
          translation -0.01 0.02 0
          children [
            Shape {
              appearance USE cacao1
              geometry Cylinder {
                height 0.15
                radius 0.03
              }
            }
          ]
        }
        Transform {
          translation 0.01 0.02 0
          children [
            Shape {
              appearance USE cacao1
              geometry Cylinder {
                height 0.15
                radius 0.03
              }
            }
          ]
        }
        Transform {
          translation 0.02 0 0
          children [
            Shape {
              appearance USE cacao1
              geometry Cylinder {
                height 0.15
                radius 0.03
              }
            }
          ]
        }
        Transform {
          translation -0.01 -0.02 0
          children [
            Shape {
              appearance USE cacao1
              geometry Cylinder {
                height 0.15
                radius 0.03
              }
            }
          ]
        }
        Transform {
          translation 0.01 -0.02 0
          children [
            Shape {
              appearance USE cacao1
              geometry Cylinder {
                height 0.15
                radius 0.03
              }
            }
          ]
        }
        Transform {
          translation 0 0 0.06
          children [
            Shape {
              appearance USE cacao1
              geometry Sphere {
                radius 0.05215
              }
            }
          ]
        }
        Transform {
          translation 0 6.10065e-07 -0.06
          rotation 1 0 0 4.692820414042842e-06
          children [
            Shape {
              appearance USE cacao1
              geometry Sphere {
                radius 0.05215
              }
            }
          ]
        }
        Transform {
          translation 0 7.03921e-07 -0.08
          rotation 1 0 0 4.692820414042842e-06
          children [
            Shape {
              appearance USE cacao1
              geometry Sphere {
                radius 0.045
              }
            }
          ]
        }
        Transform {
          translation 0 7.97777e-07 -0.1
          rotation 1 0 0 4.692820414042842e-06
          children [
            Shape {
              appearance USE cacao1
              geometry Sphere {
                radius 0.03
              }
            }
          ]
        }
        Shape {
          appearance USE cacao1
          geometry Capsule {
            height 0.16
            radius 0.04
          }
        }
      ]
    }
  ]
  name "cacao0"
  model "cacao"
  contactMaterial "cacao"
  boundingObject USE ugly_cacao
  physics Physics {
    density -1
    mass 0.5
  }
  recognitionColors [
    1 0 0
  ]
}
DEF cacao2 Solid {
  translation -0.0273435 0.486508 0.202772
  rotation 0.7040541500256862 -0.09269071975130581 -0.7040711500293086 -2.9567353071795863
  children [
    DEF ugly_cacao Group {
      children [
        Transform {
          translation -0.02 0 0
          children [
            Shape {
              appearance DEF cacao1 PBRAppearance {
                baseColor 1 0.333333 0
                metalness 0
              }
              geometry Cylinder {
                height 0.15
                radius 0.03
              }
            }
          ]
        }
        Transform {
          translation -0.01 0.02 0
          children [
            Shape {
              appearance USE cacao1
              geometry Cylinder {
                height 0.15
                radius 0.03
              }
            }
          ]
        }
        Transform {
          translation 0.01 0.02 0
          children [
            Shape {
              appearance USE cacao1
              geometry Cylinder {
                height 0.15
                radius 0.03
              }
            }
          ]
        }
        Transform {
          translation 0.02 0 0
          children [
            Shape {
              appearance USE cacao1
              geometry Cylinder {
                height 0.15
                radius 0.03
              }
            }
          ]
        }
        Transform {
          translation -0.01 -0.02 0
          children [
            Shape {
              appearance USE cacao1
              geometry Cylinder {
                height 0.15
                radius 0.03
              }
            }
          ]
        }
        Transform {
          translation 0.01 -0.02 0
          children [
            Shape {
              appearance USE cacao1
              geometry Cylinder {
                height 0.15
                radius 0.03
              }
            }
          ]
        }
        Transform {
          translation 0 0 0.06
          children [
            Shape {
              appearance USE cacao1
              geometry Sphere {
                radius 0.05215
              }
            }
          ]
        }
        Transform {
          translation 0 6.10065e-07 -0.06
          rotation 1 0 0 4.692820414042842e-06
          children [
            Shape {
              appearance USE cacao1
              geometry Sphere {
                radius 0.05215
              }
            }
          ]
        }
        Transform {
          translation 0 7.03921e-07 -0.08
          rotation 1 0 0 4.692820414042842e-06
          children [
            Shape {
              appearance USE cacao1
              geometry Sphere {
                radius 0.045
              }
            }
          ]
        }
        Transform {
          translation 0 7.97777e-07 -0.1
          rotation 1 0 0 4.692820414042842e-06
          children [
            Shape {
              appearance USE cacao1
              geometry Sphere {
                radius 0.03
              }
            }
          ]
        }
        Shape {
          appearance USE cacao1
          geometry Capsule {
            height 0.16
            radius 0.04
          }
        }
      ]
    }
  ]
  name "cacao2"
  model "cacao"
  contactMaterial "cacao"
  boundingObject USE ugly_cacao
  physics Physics {
    density -1
    mass 0.5
  }
  recognitionColors [
    1 0 0
  ]
}
DEF cacao3 Solid {
  translation 1.39866 3.96834 0.052752
  rotation 0.7070992811436049 7.252082883437699e-07 -0.7071142811495689 -3.1415853071795863
  scale 1.1 1.1 1.1
  children [
    DEF ugly_cacao Group {
      children [
        Transform {
          translation -0.02 0 0
          children [
            Shape {
              appearance DEF cacao1 PBRAppearance {
                baseColor 1 0.333333 0
                metalness 0
              }
              geometry Cylinder {
                height 0.15
                radius 0.03
              }
            }
          ]
        }
        Transform {
          translation -0.01 0.02 0
          children [
            Shape {
              appearance USE cacao1
              geometry Cylinder {
                height 0.15
                radius 0.03
              }
            }
          ]
        }
        Transform {
          translation 0.01 0.02 0
          children [
            Shape {
              appearance USE cacao1
              geometry Cylinder {
                height 0.15
                radius 0.03
              }
            }
          ]
        }
        Transform {
          translation 0.02 0 0
          children [
            Shape {
              appearance USE cacao1
              geometry Cylinder {
                height 0.15
                radius 0.03
              }
            }
          ]
        }
        Transform {
          translation -0.01 -0.02 0
          children [
            Shape {
              appearance USE cacao1
              geometry Cylinder {
                height 0.15
                radius 0.03
              }
            }
          ]
        }
        Transform {
          translation 0.01 -0.02 0
          children [
            Shape {
              appearance USE cacao1
              geometry Cylinder {
                height 0.15
                radius 0.03
              }
            }
          ]
        }
        Transform {
          translation 0 0 0.06
          children [
            Shape {
              appearance USE cacao1
              geometry Sphere {
                radius 0.05215
              }
            }
          ]
        }
        Transform {
          translation 0 6.10065e-07 -0.06
          rotation 1 0 0 4.692820414042842e-06
          children [
            Shape {
              appearance USE cacao1
              geometry Sphere {
                radius 0.05215
              }
            }
          ]
        }
        Transform {
          translation 0 7.03921e-07 -0.08
          rotation 1 0 0 4.692820414042842e-06
          children [
            Shape {
              appearance USE cacao1
              geometry Sphere {
                radius 0.045
              }
            }
          ]
        }
        Transform {
          translation 0 7.97777e-07 -0.1
          rotation 1 0 0 4.692820414042842e-06
          children [
            Shape {
              appearance USE cacao1
              geometry Sphere {
                radius 0.03
              }
            }
          ]
        }
        Shape {
          appearance USE cacao1
          geometry Capsule {
            height 0.16
            radius 0.04
          }
        }
      ]
    }
  ]
  name "cacao3"
  model "cacao"
  contactMaterial "cacao"
  boundingObject USE ugly_cacao
  physics Physics {
    density -1
    mass 0.5
  }
  recognitionColors [
    1 0 0
  ]
}
DEF cacao4 Solid {
  translation 0.051191 1.36538 0.0527717
  rotation 0.5773459358484986 0.5773529358477207 -0.5773519358478318 2.09442
  scale 0.9 0.9 0.9
  children [
    DEF ugly_cacao Group {
      children [
        Transform {
          translation -0.02 0 0
          children [
            Shape {
              appearance DEF cacao1 PBRAppearance {
                baseColor 1 0.333333 0
                metalness 0
              }
              geometry Cylinder {
                height 0.15
                radius 0.03
              }
            }
          ]
        }
        Transform {
          translation -0.01 0.02 0
          children [
            Shape {
              appearance USE cacao1
              geometry Cylinder {
                height 0.15
                radius 0.03
              }
            }
          ]
        }
        Transform {
          translation 0.01 0.02 0
          children [
            Shape {
              appearance USE cacao1
              geometry Cylinder {
                height 0.15
                radius 0.03
              }
            }
          ]
        }
        Transform {
          translation 0.02 0 0
          children [
            Shape {
              appearance USE cacao1
              geometry Cylinder {
                height 0.15
                radius 0.03
              }
            }
          ]
        }
        Transform {
          translation -0.01 -0.02 0
          children [
            Shape {
              appearance USE cacao1
              geometry Cylinder {
                height 0.15
                radius 0.03
              }
            }
          ]
        }
        Transform {
          translation 0.01 -0.02 0
          children [
            Shape {
              appearance USE cacao1
              geometry Cylinder {
                height 0.15
                radius 0.03
              }
            }
          ]
        }
        Transform {
          translation 0 0 0.06
          children [
            Shape {
              appearance USE cacao1
              geometry Sphere {
                radius 0.05215
              }
            }
          ]
        }
        Transform {
          translation 0 6.10065e-07 -0.06
          rotation 1 0 0 4.692820414042842e-06
          children [
            Shape {
              appearance USE cacao1
              geometry Sphere {
                radius 0.05215
              }
            }
          ]
        }
        Transform {
          translation 0 7.03921e-07 -0.08
          rotation 1 0 0 4.692820414042842e-06
          children [
            Shape {
              appearance USE cacao1
              geometry Sphere {
                radius 0.045
              }
            }
          ]
        }
        Transform {
          translation 0 7.97777e-07 -0.1
          rotation 1 0 0 4.692820414042842e-06
          children [
            Shape {
              appearance USE cacao1
              geometry Sphere {
                radius 0.03
              }
            }
          ]
        }
        Shape {
          appearance USE cacao1
          geometry Capsule {
            height 0.16
            radius 0.04
          }
        }
      ]
    }
  ]
  name "cacao4"
  model "cacao"
  contactMaterial "cacao"
  boundingObject USE ugly_cacao
  physics Physics {
    density -1
    mass 0.5
  }
  recognitionColors [
    1 0 0
  ]
}
DEF cacao5 Solid {
  translation 0.0611853 2.66538 0.05277
  rotation 0.5773459358484986 0.5773529358477207 -0.5773519358478318 2.09442
  scale 0.9 0.9 0.9
  children [
    DEF ugly_cacao Group {
      children [
        Transform {
          translation -0.02 0 0
          children [
            Shape {
              appearance DEF cacao1 PBRAppearance {
                baseColor 1 0.333333 0
                metalness 0
              }
              geometry Cylinder {
                height 0.15
                radius 0.03
              }
            }
          ]
        }
        Transform {
          translation -0.01 0.02 0
          children [
            Shape {
              appearance USE cacao1
              geometry Cylinder {
                height 0.15
                radius 0.03
              }
            }
          ]
        }
        Transform {
          translation 0.01 0.02 0
          children [
            Shape {
              appearance USE cacao1
              geometry Cylinder {
                height 0.15
                radius 0.03
              }
            }
          ]
        }
        Transform {
          translation 0.02 0 0
          children [
            Shape {
              appearance USE cacao1
              geometry Cylinder {
                height 0.15
                radius 0.03
              }
            }
          ]
        }
        Transform {
          translation -0.01 -0.02 0
          children [
            Shape {
              appearance USE cacao1
              geometry Cylinder {
                height 0.15
                radius 0.03
              }
            }
          ]
        }
        Transform {
          translation 0.01 -0.02 0
          children [
            Shape {
              appearance USE cacao1
              geometry Cylinder {
                height 0.15
                radius 0.03
              }
            }
          ]
        }
        Transform {
          translation 0 0 0.06
          children [
            Shape {
              appearance USE cacao1
              geometry Sphere {
                radius 0.05215
              }
            }
          ]
        }
        Transform {
          translation 0 6.10065e-07 -0.06
          rotation 1 0 0 4.692820414042842e-06
          children [
            Shape {
              appearance USE cacao1
              geometry Sphere {
                radius 0.05215
              }
            }
          ]
        }
        Transform {
          translation 0 7.03921e-07 -0.08
          rotation 1 0 0 4.692820414042842e-06
          children [
            Shape {
              appearance USE cacao1
              geometry Sphere {
                radius 0.045
              }
            }
          ]
        }
        Transform {
          translation 0 7.97777e-07 -0.1
          rotation 1 0 0 4.692820414042842e-06
          children [
            Shape {
              appearance USE cacao1
              geometry Sphere {
                radius 0.03
              }
            }
          ]
        }
        Shape {
          appearance USE cacao1
          geometry Capsule {
            height 0.16
            radius 0.04
          }
        }
      ]
    }
  ]
  name "cacao5"
  model "cacao"
  contactMaterial "cacao"
  boundingObject USE ugly_cacao
  physics Physics {
    density -1
    mass 0.5
  }
  recognitionColors [
    1 0 0
  ]
}
